Workbook

Sheet Optimal Setup
I1: Enter Max: | L1: Enter average load: | P1: Variation factor + - | Q1: Battery peak shaving (+ - ) | R1: Spinning reserve | Y1: Load (%) | Z1: SFOC (g/kwh)
A2: Max battery peak shaving and reserve capacity | I2: 1260 | L2: DP Redundancy | O2: 0 | P2: 0 | Q2: ='Load Demands'!J5 -> 0 | R2: ='Load Demands'!L5 -> 0 | Z2: G1 | AA2: G6 | AB2: G2 | AC2: G3 | AD2: G4 | AE2: G5
A3: Mission HVY consumer load expected at its max load: | I3: 3000 | L3: DP (Thruster) load demand: | O3: 0 | P3: 0 | Q3: ='Load Demands'!J6 -> 0 | R3: ='Load Demands'!L6 -> 0 | Y3: 0.001 | Z3: 174.476 | AA3: 174.476 | AB3: 228.4744 | AC3: 228.70287 | AD3: 218.83278 | AE3: 251.32184
A4: Losses for PTI propulsion | I4: 0.05 | L4: Mission load demand: | O4: 0 | Q4: ='Load Demands'!J7 -> 0 | R4: ='Load Demands'!L7 -> 0 | Y4: 0.1 | Z4: 174.476 | AA4: 174.476 | AB4: 228.4744 | AC4: 228.70287 | AD4: 218.83278 | AE4: 251.32184
L5: Propeller load demand: | O5: 11463 | P5: 0.05 | Q5: =-1*'Load Demands'!J8 -> -200.6025 | R5: ='Load Demands'!L8 -> 372.5475 | S5: * PTI available? | Y5: 0.2 | Z5: 174.476 | AA5: 174.476 | AB5: 228 | AC5: 228.228 | AD5: 218.3784 | AE5: 250.8
B6: Enter Max load: | L6: Hotel load demand: | O6: 3800 | P6: 0.02 | Q6: =-1*'Load Demands'!J9 -> -3.8 | R6: ='Load Demands'!L9 -> 72.2 | Y6: 0.3 | Z6: 172.568 | AA6: 172.568 | AB6: 220 | AC6: 220.22 | AD6: 210.716 | AE6: 242
O7: =SUM(O3:O6) -> 15263 | Q7: =SUM(Q2:Q6) -> -204.4025 | R7: =SUM(R2:R6) -> 444.7475 | Y7: 0.4 | Z7: 170 | AA7: 170 | AB7: 198 | AC7: 198.198 | AD7: 189.6444 | AE7: 217.8
B8: Prop 1 | C8: Prop 2 | D8: Aux | E8: Aux | F8: Aux | G8: Aux | H8: Max | I8: Max | L8: Total demand: | R8: =O7+R7 -> 15707.747 | Y8: 0.5 | Z8: 166.42 | AA8: 166.42 | AB8: 198.0671 | AC8: 198.26517 | AD8: 189.70867 | AE8: 217.87381
B9: G1 | C9: G6 | D9: G2 | E9: G3 | F9: G4 | G9: G5 | H9: Propulsion | I9: Aux | Y9: 0.6 | Z9: 166 | AA9: 166 | AB9: 195 | AC9: 195.195 | AD9: 186.771 | AE9: 214.5
A10: Max Gen | B10: 24000 | C10: 24000 | D10: 4000 | E10: 4000 | F10: 4000 | G10: 4000 | H10: =SUM(B10:C10) -> 48000 | I10: =SUM(D10:G10) -> 16000 | Y10: 0.7 | Z10: 167.268 | AA10: 167.268 | AB10: 193.13488 | AC10: 193.32801 | AD10: 184.98459 | AE10: 212.44837
A11: Max PTI | B11: 3250 | C11: 3250 | H11: =SUM(B11:C11) -> 6500 | Y11: 0.8 | Z11: 168 | AA11: 168 | AB11: 193.3624 | AC11: 193.55576 | AD11: 185.20251 | AE11: 212.69864
A12: MAX ME + PTI | B12: =SUM(B10:B11) -> 27250 | C12: =SUM(C10:C11) -> 27250 | D12: =0 -> 0 | E12: =0 -> 0 | F12: =0 -> 0 | G12: =0 -> 0 | H12: =SUM(H10:H11) -> 54500 | N12: ME loss for power to hotel load (SG PTO - switchboard) is ~ the same as for Aux gensets | Y12: 0.9 | Z12: 168.222 | AA12: 168.222 | AB12: 194 | AC12: 194.194 | AD12: 185.8132 | AE12: 213.4
A13: Max PTO | B13: 3250 | C13: 3250 | H13: =SUM(B13:C13) -> 6500 | N13: G2 - G5 loss for propulsion power is ~6-15% higher than directly from Engine (mechanical shaft) | Y13: 1 | Z13: 174.476 | AA13: 174.476 | AB13: 194.629 | AC13: 194.82363 | AD13: 186.41566 | AE13: 214.0919
A14: MAX Aux + PTO | B14: =B13 -> 3250 | C14: =C13 -> 3250 | D14: =D10 -> 4000 | E14: =E10 -> 4000 | F14: =F10 -> 4000 | G14: =G10 -> 4000 | H14: =SUM(H12:H13) -> 61000
J16: Total PWR | K16: ME | M16: Propulsion ME DEMAND -> | P16: AUX | T16: SG 1 | V16: SG 2 | X16: PTI - PS | Y16: PTO- PS | Z16: SFOC (g/kwh) : | AF16: TOTAL SFOC | AG16: RECOMENDED ENGINES/GENERATORS:
B17: G1 | C17: G6 | D17: G2 | E17: G3 | F17: G4 | G17: G5 | I17: Total: % Demand of Max | J17: Setup MAX | K17: ME MAX | L17: Total DEMAND from ME | M17: Needed PTI PROP / PTO for Hotel | N17: for PTI 1 | O17: Remaining PTI (after PTI 2) | P17: AUX MAX | Q17: Additional power/Load for PTI propulsion on AUX gens due to losses | R17: Total DEMAND from AUX | S17: Aux: % Demand of Max | T17: PTI 1 | U17: PTO 1 | V17: PTI 2 | W17: PTO 2 | X17: Available PTI for Peak shaving from battery | Y17: Available PTO for Peak shaving to battery | Z17: G1 | AA17: G6 | AB17: G2 | AC17: G3 | AD17: G4 | AE17: G5 | AF17: =MIN(AF18:AF75) -> 344 | AG17: ME | AH17: =IF(AND($AF16=$AF$17,C17=1),C$9,"") | AI17: Aux | AJ17: =IF(AND($AF16=$AF$17,E17=1),E$9,"")
A18: Setup variants: | D18: 1 | H18: =IF($R$8>$J18,"Insufficient pwr",IF(OR(($M18-$T18-$V18)>0,$X18<$Q$5),"Insufficient PTI",IF(OR(($M18+$U18+$W18)<0,$Y18<$Q$5),"Insufficient PTO",IF(($P18-$R18)<0,"Insufficient AUX","")))) -> Insufficient pwr | I18: =$R$8/$J18 -> 3.9269369 | J18: =B18*B$10+D18*D$10+E18*E$10+F18*F$10+G18*G$10+C18*C$10 -> 4000 | K18: =IF($B18,$B$10)+IF($C18,$C$10) -> 0 | L18: =(IF($B18,$B$10)+IF($C18,$C$10))*$I18 -> 0 | M18: =$O$5-$L18 -> 11463 | N18: =IF(AND($B18="",$M18>0),MIN($M18,$B$11),0) -> 3250 | O18: =IF($M18<0,0,$M18-$N18-$V18) -> 4963 | P18: =IF($D18,$D$10)+IF($E18,$E$10)+IF($F18,$F$10)+IF($G18,$G$10) -> 4000 | Q18: =IF($M18<0,0,$M18*$I$4) -> 573.15 | R18: =(IF($D18,$D$10)+IF($E18,$E$10)+IF($F18,$F$10)+IF($G18,$G$10))*$I18+$Q18 -> 16280.897 | S18: =IF($P18=0,0,$R18/$P18) -> 4.0702244 | T18: =IF($M18<0,0,MIN(($N18+$O18),$B$11)) -> 3250 | U18: =IF(AND($B18=1,$M18<0),MIN(ABS($M18),$B$13),0) -> 0 | V18: =IF($M18<0,0,MIN(($M18-$N18),$C$11)) -> 3250 | W18: =IF(AND($C18=1,$M18<0),MIN((ABS($M18)-$U18),$C$13),0) -> 0 | X18: =IF(IF(U18>0,0,$B$11-T18)+IF(W18>0,0,$C$11-V18)>$Q$5,$Q$5,IF(U18>0,0,$B$11-T18)+IF(W18>0,0,$C$11-V18)) -> -200.6025 | Y18: =IF(IF(T18>0,0,$B$11-U18)+IF(V18>0,0,$C$11-W18)>$Q$5,$Q$5,IF(T18>0,0,$B$11-U18)+IF(V18>0,0,$C$11-W18)) -> -200.6025 | Z18: =IF(OR(B18="",NOT($H18="")),"",ROUND(_xlfn.FORECAST.LINEAR($I18,INDEX(Z$3:Z$13,MATCH($I18,$Y$3:$Y$13,1)):INDEX(Z$3:Z$13,MATCH($I18,$Y$3:$Y$13,1)+1),INDEX($Y$3:$Y$13,MATCH($I18,$Y$3:$Y$13,1)):INDEX($Y$3:$Y$13,MATCH($I18,$Y$3:$Y$13,1)+1)),0)) | AA18: =IF(OR(C18="",NOT($H18="")),"",ROUND(_xlfn.FORECAST.LINEAR($I18,INDEX(AA$3:AA$13,MATCH($I18,$Y$3:$Y$13,1)):INDEX(AA$3:AA$13,MATCH($I18,$Y$3:$Y$13,1)+1),INDEX($Y$3:$Y$13,MATCH($I18,$Y$3:$Y$13,1)):INDEX($Y$3:$Y$13,MATCH($I18,$Y$3:$Y$13,1)+1)),0)) | AB18: =IF(OR(D18="",NOT($H18="")),"",ROUND(_xlfn.FORECAST.LINEAR($S18,INDEX(AB$3:AB$13,MATCH($S18,$Y$3:$Y$13,1)):INDEX(AB$3:AB$13,MATCH($S18,$Y$3:$Y$13,1)+1),INDEX($Y$3:$Y$13,MATCH($S18,$Y$3:$Y$13,1)):INDEX($Y$3:$Y$13,MATCH($S18,$Y$3:$Y$13,1)+1)),0)) | AC18: =IF(OR(E18="",NOT($H18="")),"",ROUND(_xlfn.FORECAST.LINEAR($S18,INDEX(AC$3:AC$13,MATCH($S18,$Y$3:$Y$13,1)):INDEX(AC$3:AC$13,MATCH($S18,$Y$3:$Y$13,1)+1),INDEX($Y$3:$Y$13,MATCH($S18,$Y$3:$Y$13,1)):INDEX($Y$3:$Y$13,MATCH($S18,$Y$3:$Y$13,1)+1)),0)) | AD18: =IF(OR(F18="",NOT($H18="")),"",ROUND(_xlfn.FORECAST.LINEAR($S18,INDEX(AD$3:AD$13,MATCH($S18,$Y$3:$Y$13,1)):INDEX(AD$3:AD$13,MATCH($S18,$Y$3:$Y$13,1)+1),INDEX($Y$3:$Y$13,MATCH($S18,$Y$3:$Y$13,1)):INDEX($Y$3:$Y$13,MATCH($S18,$Y$3:$Y$13,1)+1)),0)) | AE18: =IF(OR(G18="",NOT($H18="")),"",ROUND(_xlfn.FORECAST.LINEAR($S18,INDEX(AE$3:AE$13,MATCH($S18,$Y$3:$Y$13,1)):INDEX(AE$3:AE$13,MATCH($S18,$Y$3:$Y$13,1)+1),INDEX($Y$3:$Y$13,MATCH($S18,$Y$3:$Y$13,1)):INDEX($Y$3:$Y$13,MATCH($S18,$Y$3:$Y$13,1)+1)),0)) | AF18: =IF($H18="",SUM(Z18:AE18),"") | AG18: =IF(AND($AF18=$AF$17,B18=1),B$9,"") | AH18: =IF(AND($AF18=$AF$17,C18=1),C$9,"") | AI18: =IF(AND($AF18=$AF$17,D18=1),D$9,"") | AJ18: =IF(AND($AF18=$AF$17,E18=1),E$9,"") | AK18: =IF(AND($AF18=$AF$17,F18=1),F$9,"") | AL18: =IF(AND($AF18=$AF$17,G18=1),G$9,"")
E19: 1 | H19: =IF($R$8>$J19,"Insufficient pwr",IF(OR(($M19-$T19-$V19)>0,$X19<$Q$5),"Insufficient PTI",IF(OR(($M19+$U19+$W19)<0,$Y19<$Q$5),"Insufficient PTO",IF(($P19-$R19)<0,"Insufficient AUX","")))) -> Insufficient pwr | I19: =$R$8/$J19 -> 3.9269369 | J19: =B19*B$10+D19*D$10+E19*E$10+F19*F$10+G19*G$10+C19*C$10 -> 4000 | K19: =IF($B19,$B$10)+IF($C19,$C$10) -> 0 | L19: =(IF($B19,$B$10)+IF($C19,$C$10))*$I19 -> 0 | M19: =$O$5-$L19 -> 11463 | N19: =IF(AND($B19="",$M19>0),MIN($M19,$B$11),0) -> 3250 | O19: =IF($M19<0,0,$M19+$Q19-$N19-$V19) -> 5536.15 | P19: =IF($D19,$D$10)+IF($E19,$E$10)+IF($F19,$F$10)+IF($G19,$G$10) -> 4000 | Q19: =IF($M19<0,0,$M19*$I$4) -> 573.15 | R19: =(IF($D19,$D$10)+IF($E19,$E$10)+IF($F19,$F$10)+IF($G19,$G$10))*$I19+$Q19 -> 16280.897 | S19: =IF($P19=0,0,$R19/$P19) -> 4.0702244 | T19: =IF($M19<0,0,MIN(($N19+$O19),$B$11)) -> 3250 | U19: =IF(AND($B19=1,$M19<0),MIN(ABS($M19),$B$13),0) -> 0 | V19: =IF($M19<0,0,MIN(($M19-$N19),$C$11)) -> 3250 | W19: =IF(AND($C19=1,$M19<0),MIN((ABS($M19)-$U19),$C$13),0) -> 0 | X19: =IF(IF(U19>0,0,$B$11-T19)+IF(W19>0,0,$C$11-V19)>$Q$5,$Q$5,IF(U19>0,0,$B$11-T19)+IF(W19>0,0,$C$11-V19)) -> -200.6025 | Y19: =IF(IF(T19>0,0,$B$11-U19)+IF(V19>0,0,$C$11-W19)>$Q$5,$Q$5,IF(T19>0,0,$B$11-U19)+IF(V19>0,0,$C$11-W19)) -> -200.6025 | Z19: =IF(OR(B19="",NOT($H19="")),"",ROUND(_xlfn.FORECAST.LINEAR($I19,INDEX(Z$3:Z$13,MATCH($I19,$Y$3:$Y$13,1)):INDEX(Z$3:Z$13,MATCH($I19,$Y$3:$Y$13,1)+1),INDEX($Y$3:$Y$13,MATCH($I19,$Y$3:$Y$13,1)):INDEX($Y$3:$Y$13,MATCH($I19,$Y$3:$Y$13,1)+1)),0)) | AA19: =IF(OR(C19="",NOT($H19="")),"",ROUND(_xlfn.FORECAST.LINEAR($I19,INDEX(AA$3:AA$13,MATCH($I19,$Y$3:$Y$13,1)):INDEX(AA$3:AA$13,MATCH($I19,$Y$3:$Y$13,1)+1),INDEX($Y$3:$Y$13,MATCH($I19,$Y$3:$Y$13,1)):INDEX($Y$3:$Y$13,MATCH($I19,$Y$3:$Y$13,1)+1)),0)) | AB19: =IF(OR(D19="",NOT($H19="")),"",ROUND(_xlfn.FORECAST.LINEAR($S19,INDEX(AB$3:AB$13,MATCH($S19,$Y$3:$Y$13,1)):INDEX(AB$3:AB$13,MATCH($S19,$Y$3:$Y$13,1)+1),INDEX($Y$3:$Y$13,MATCH($S19,$Y$3:$Y$13,1)):INDEX($Y$3:$Y$13,MATCH($S19,$Y$3:$Y$13,1)+1)),0)) | AC19: =IF(OR(E19="",NOT($H19="")),"",ROUND(_xlfn.FORECAST.LINEAR($S19,INDEX(AC$3:AC$13,MATCH($S19,$Y$3:$Y$13,1)):INDEX(AC$3:AC$13,MATCH($S19,$Y$3:$Y$13,1)+1),INDEX($Y$3:$Y$13,MATCH($S19,$Y$3:$Y$13,1)):INDEX($Y$3:$Y$13,MATCH($S19,$Y$3:$Y$13,1)+1)),0)) | AD19: =IF(OR(F19="",NOT($H19="")),"",ROUND(_xlfn.FORECAST.LINEAR($S19,INDEX(AD$3:AD$13,MATCH($S19,$Y$3:$Y$13,1)):INDEX(AD$3:AD$13,MATCH($S19,$Y$3:$Y$13,1)+1),INDEX($Y$3:$Y$13,MATCH($S19,$Y$3:$Y$13,1)):INDEX($Y$3:$Y$13,MATCH($S19,$Y$3:$Y$13,1)+1)),0)) | AE19: =IF(OR(G19="",NOT($H19="")),"",ROUND(_xlfn.FORECAST.LINEAR($S19,INDEX(AE$3:AE$13,MATCH($S19,$Y$3:$Y$13,1)):INDEX(AE$3:AE$13,MATCH($S19,$Y$3:$Y$13,1)+1),INDEX($Y$3:$Y$13,MATCH($S19,$Y$3:$Y$13,1)):INDEX($Y$3:$Y$13,MATCH($S19,$Y$3:$Y$13,1)+1)),0)) | AF19: =IF($H19="",SUM(Z19:AE19),"") | AG19: =IF(AND($AF19=$AF$17,B19=1),B$9,"") | AH19: =IF(AND($AF19=$AF$17,C19=1),C$9,"") | AI19: =IF(AND($AF19=$AF$17,D19=1),D$9,"") | AJ19: =IF(AND($AF19=$AF$17,E19=1),E$9,"") | AK19: =IF(AND($AF19=$AF$17,F19=1),F$9,"") | AL19: =IF(AND($AF19=$AF$17,G19=1),G$9,"")
F20: 1 | H20: =IF($R$8>$J20,"Insufficient pwr",IF(OR(($M20-$T20-$V20)>0,$X20<$Q$5),"Insufficient PTI",IF(OR(($M20+$U20+$W20)<0,$Y20<$Q$5),"Insufficient PTO",IF(($P20-$R20)<0,"Insufficient AUX","")))) -> Insufficient pwr | I20: =$R$8/$J20 -> 3.9269369 | J20: =B20*B$10+D20*D$10+E20*E$10+F20*F$10+G20*G$10+C20*C$10 -> 4000 | K20: =IF($B20,$B$10)+IF($C20,$C$10) -> 0 | L20: =(IF($B20,$B$10)+IF($C20,$C$10))*$I20 -> 0 | M20: =$O$5-$L20 -> 11463 | N20: =IF(AND($B20="",$M20>0),MIN($M20,$B$11),0) -> 3250 | O20: =IF($M20<0,0,$M20+$Q20-$N20-$V20) -> 5536.15 | P20: =IF($D20,$D$10)+IF($E20,$E$10)+IF($F20,$F$10)+IF($G20,$G$10) -> 4000 | Q20: =IF($M20<0,0,$M20*$I$4) -> 573.15 | R20: =(IF($D20,$D$10)+IF($E20,$E$10)+IF($F20,$F$10)+IF($G20,$G$10))*$I20+$Q20 -> 16280.897 | S20: =IF($P20=0,0,$R20/$P20) -> 4.0702244 | T20: =IF($M20<0,0,MIN(($N20+$O20),$B$11)) -> 3250 | U20: =IF(AND($B20=1,$M20<0),MIN(ABS($M20),$B$13),0) -> 0 | V20: =IF($M20<0,0,MIN(($M20-$N20),$C$11)) -> 3250 | W20: =IF(AND($C20=1,$M20<0),MIN((ABS($M20)-$U20),$C$13),0) -> 0 | X20: =IF(IF(U20>0,0,$B$11-T20)+IF(W20>0,0,$C$11-V20)>$Q$5,$Q$5,IF(U20>0,0,$B$11-T20)+IF(W20>0,0,$C$11-V20)) -> -200.6025 | Y20: =IF(IF(T20>0,0,$B$11-U20)+IF(V20>0,0,$C$11-W20)>$Q$5,$Q$5,IF(T20>0,0,$B$11-U20)+IF(V20>0,0,$C$11-W20)) -> -200.6025 | Z20: =IF(OR(B20="",NOT($H20="")),"",ROUND(_xlfn.FORECAST.LINEAR($I20,INDEX(Z$3:Z$13,MATCH($I20,$Y$3:$Y$13,1)):INDEX(Z$3:Z$13,MATCH($I20,$Y$3:$Y$13,1)+1),INDEX($Y$3:$Y$13,MATCH($I20,$Y$3:$Y$13,1)):INDEX($Y$3:$Y$13,MATCH($I20,$Y$3:$Y$13,1)+1)),0)) | AA20: =IF(OR(C20="",NOT($H20="")),"",ROUND(_xlfn.FORECAST.LINEAR($I20,INDEX(AA$3:AA$13,MATCH($I20,$Y$3:$Y$13,1)):INDEX(AA$3:AA$13,MATCH($I20,$Y$3:$Y$13,1)+1),INDEX($Y$3:$Y$13,MATCH($I20,$Y$3:$Y$13,1)):INDEX($Y$3:$Y$13,MATCH($I20,$Y$3:$Y$13,1)+1)),0)) | AB20: =IF(OR(D20="",NOT($H20="")),"",ROUND(_xlfn.FORECAST.LINEAR($S20,INDEX(AB$3:AB$13,MATCH($S20,$Y$3:$Y$13,1)):INDEX(AB$3:AB$13,MATCH($S20,$Y$3:$Y$13,1)+1),INDEX($Y$3:$Y$13,MATCH($S20,$Y$3:$Y$13,1)):INDEX($Y$3:$Y$13,MATCH($S20,$Y$3:$Y$13,1)+1)),0)) | AC20: =IF(OR(E20="",NOT($H20="")),"",ROUND(_xlfn.FORECAST.LINEAR($S20,INDEX(AC$3:AC$13,MATCH($S20,$Y$3:$Y$13,1)):INDEX(AC$3:AC$13,MATCH($S20,$Y$3:$Y$13,1)+1),INDEX($Y$3:$Y$13,MATCH($S20,$Y$3:$Y$13,1)):INDEX($Y$3:$Y$13,MATCH($S20,$Y$3:$Y$13,1)+1)),0)) | AD20: =IF(OR(F20="",NOT($H20="")),"",ROUND(_xlfn.FORECAST.LINEAR($S20,INDEX(AD$3:AD$13,MATCH($S20,$Y$3:$Y$13,1)):INDEX(AD$3:AD$13,MATCH($S20,$Y$3:$Y$13,1)+1),INDEX($Y$3:$Y$13,MATCH($S20,$Y$3:$Y$13,1)):INDEX($Y$3:$Y$13,MATCH($S20,$Y$3:$Y$13,1)+1)),0)) | AE20: =IF(OR(G20="",NOT($H20="")),"",ROUND(_xlfn.FORECAST.LINEAR($S20,INDEX(AE$3:AE$13,MATCH($S20,$Y$3:$Y$13,1)):INDEX(AE$3:AE$13,MATCH($S20,$Y$3:$Y$13,1)+1),INDEX($Y$3:$Y$13,MATCH($S20,$Y$3:$Y$13,1)):INDEX($Y$3:$Y$13,MATCH($S20,$Y$3:$Y$13,1)+1)),0)) | AF20: =IF($H20="",SUM(Z20:AE20),"") | AG20: =IF(AND($AF20=$AF$17,B20=1),B$9,"") | AH20: =IF(AND($AF20=$AF$17,C20=1),C$9,"") | AI20: =IF(AND($AF20=$AF$17,D20=1),D$9,"") | AJ20: =IF(AND($AF20=$AF$17,E20=1),E$9,"") | AK20: =IF(AND($AF20=$AF$17,F20=1),F$9,"") | AL20: =IF(AND($AF20=$AF$17,G20=1),G$9,"")
G21: 1 | H21: =IF($R$8>$J21,"Insufficient pwr",IF(OR(($M21-$T21-$V21)>0,$X21<$Q$5),"Insufficient PTI",IF(OR(($M21+$U21+$W21)<0,$Y21<$Q$5),"Insufficient PTO",IF(($P21-$R21)<0,"Insufficient AUX","")))) -> Insufficient pwr | I21: =$R$8/$J21 -> 3.9269369 | J21: =B21*B$10+D21*D$10+E21*E$10+F21*F$10+G21*G$10+C21*C$10 -> 4000 | K21: =IF($B21,$B$10)+IF($C21,$C$10) -> 0 | L21: =(IF($B21,$B$10)+IF($C21,$C$10))*$I21 -> 0 | M21: =$O$5-$L21 -> 11463 | N21: =IF(AND($B21="",$M21>0),MIN($M21,$B$11),0) -> 3250 | O21: =IF($M21<0,0,$M21+$Q21-$N21-$V21) -> 5536.15 | P21: =IF($D21,$D$10)+IF($E21,$E$10)+IF($F21,$F$10)+IF($G21,$G$10) -> 4000 | Q21: =IF($M21<0,0,$M21*$I$4) -> 573.15 | R21: =(IF($D21,$D$10)+IF($E21,$E$10)+IF($F21,$F$10)+IF($G21,$G$10))*$I21+$Q21 -> 16280.897 | S21: =IF($P21=0,0,$R21/$P21) -> 4.0702244 | T21: =IF($M21<0,0,MIN(($N21+$O21),$B$11)) -> 3250 | U21: =IF(AND($B21=1,$M21<0),MIN(ABS($M21),$B$13),0) -> 0 | V21: =IF($M21<0,0,MIN(($M21-$N21),$C$11)) -> 3250 | W21: =IF(AND($C21=1,$M21<0),MIN((ABS($M21)-$U21),$C$13),0) -> 0 | X21: =IF(IF(U21>0,0,$B$11-T21)+IF(W21>0,0,$C$11-V21)>$Q$5,$Q$5,IF(U21>0,0,$B$11-T21)+IF(W21>0,0,$C$11-V21)) -> -200.6025 | Y21: =IF(IF(T21>0,0,$B$11-U21)+IF(V21>0,0,$C$11-W21)>$Q$5,$Q$5,IF(T21>0,0,$B$11-U21)+IF(V21>0,0,$C$11-W21)) -> -200.6025 | Z21: =IF(OR(B21="",NOT($H21="")),"",ROUND(_xlfn.FORECAST.LINEAR($I21,INDEX(Z$3:Z$13,MATCH($I21,$Y$3:$Y$13,1)):INDEX(Z$3:Z$13,MATCH($I21,$Y$3:$Y$13,1)+1),INDEX($Y$3:$Y$13,MATCH($I21,$Y$3:$Y$13,1)):INDEX($Y$3:$Y$13,MATCH($I21,$Y$3:$Y$13,1)+1)),0)) | AA21: =IF(OR(C21="",NOT($H21="")),"",ROUND(_xlfn.FORECAST.LINEAR($I21,INDEX(AA$3:AA$13,MATCH($I21,$Y$3:$Y$13,1)):INDEX(AA$3:AA$13,MATCH($I21,$Y$3:$Y$13,1)+1),INDEX($Y$3:$Y$13,MATCH($I21,$Y$3:$Y$13,1)):INDEX($Y$3:$Y$13,MATCH($I21,$Y$3:$Y$13,1)+1)),0)) | AB21: =IF(OR(D21="",NOT($H21="")),"",ROUND(_xlfn.FORECAST.LINEAR($S21,INDEX(AB$3:AB$13,MATCH($S21,$Y$3:$Y$13,1)):INDEX(AB$3:AB$13,MATCH($S21,$Y$3:$Y$13,1)+1),INDEX($Y$3:$Y$13,MATCH($S21,$Y$3:$Y$13,1)):INDEX($Y$3:$Y$13,MATCH($S21,$Y$3:$Y$13,1)+1)),0)) | AC21: =IF(OR(E21="",NOT($H21="")),"",ROUND(_xlfn.FORECAST.LINEAR($S21,INDEX(AC$3:AC$13,MATCH($S21,$Y$3:$Y$13,1)):INDEX(AC$3:AC$13,MATCH($S21,$Y$3:$Y$13,1)+1),INDEX($Y$3:$Y$13,MATCH($S21,$Y$3:$Y$13,1)):INDEX($Y$3:$Y$13,MATCH($S21,$Y$3:$Y$13,1)+1)),0)) | AD21: =IF(OR(F21="",NOT($H21="")),"",ROUND(_xlfn.FORECAST.LINEAR($S21,INDEX(AD$3:AD$13,MATCH($S21,$Y$3:$Y$13,1)):INDEX(AD$3:AD$13,MATCH($S21,$Y$3:$Y$13,1)+1),INDEX($Y$3:$Y$13,MATCH($S21,$Y$3:$Y$13,1)):INDEX($Y$3:$Y$13,MATCH($S21,$Y$3:$Y$13,1)+1)),0)) | AE21: =IF(OR(G21="",NOT($H21="")),"",ROUND(_xlfn.FORECAST.LINEAR($S21,INDEX(AE$3:AE$13,MATCH($S21,$Y$3:$Y$13,1)):INDEX(AE$3:AE$13,MATCH($S21,$Y$3:$Y$13,1)+1),INDEX($Y$3:$Y$13,MATCH($S21,$Y$3:$Y$13,1)):INDEX($Y$3:$Y$13,MATCH($S21,$Y$3:$Y$13,1)+1)),0)) | AF21: =IF($H21="",SUM(Z21:AE21),"") | AG21: =IF(AND($AF21=$AF$17,B21=1),B$9,"") | AH21: =IF(AND($AF21=$AF$17,C21=1),C$9,"") | AI21: =IF(AND($AF21=$AF$17,D21=1),D$9,"") | AJ21: =IF(AND($AF21=$AF$17,E21=1),E$9,"") | AK21: =IF(AND($AF21=$AF$17,F21=1),F$9,"") | AL21: =IF(AND($AF21=$AF$17,G21=1),G$9,"")
B22: 1 | H22: =IF($R$8>$J22,"Insufficient pwr",IF(OR(($M22-$T22-$V22)>0,$X22<$Q$5),"Insufficient PTI",IF(OR(($M22+$U22+$W22)<0,$Y22<$Q$5),"Insufficient PTO",IF(($P22-$R22)<0,"Insufficient AUX","")))) -> Insufficient PTO | I22: =$R$8/$J22 -> 0.65448948 | J22: =B22*B$10+D22*D$10+E22*E$10+F22*F$10+G22*G$10+C22*C$10 -> 24000 | K22: =IF($B22,$B$10)+IF($C22,$C$10) -> 24000 | L22: =(IF($B22,$B$10)+IF($C22,$C$10))*$I22 -> 15707.747 | M22: =$O$5-$L22 -> -4244.7475 | N22: =IF(AND($B22="",$M22>0),MIN($M22,$B$11),0) -> 0 | O22: =IF($M22<0,0,$M22+$Q22-$N22-$V22) -> 0 | P22: =IF($D22,$D$10)+IF($E22,$E$10)+IF($F22,$F$10)+IF($G22,$G$10) -> 0 | Q22: =IF($M22<0,0,$M22*$I$4) -> 0 | R22: =(IF($D22,$D$10)+IF($E22,$E$10)+IF($F22,$F$10)+IF($G22,$G$10))*$I22+$Q22 -> 0 | S22: =IF($P22=0,0,$R22/$P22) -> 0 | T22: =IF($M22<0,0,MIN(($N22+$O22),$B$11)) -> 0 | U22: =IF(AND($B22=1,$M22<0),MIN(ABS($M22),$B$13),0) -> 3250 | V22: =IF($M22<0,0,MIN(($M22-$N22),$C$11)) -> 0 | W22: =IF(AND($C22=1,$M22<0),MIN((ABS($M22)-$U22),$C$13),0) -> 0 | X22: =IF(IF(U22>0,0,$B$11-T22)+IF(W22>0,0,$C$11-V22)>$Q$5,$Q$5,IF(U22>0,0,$B$11-T22)+IF(W22>0,0,$C$11-V22)) -> -200.6025 | Y22: =IF(IF(T22>0,0,$B$11-U22)+IF(V22>0,0,$C$11-W22)>$Q$5,$Q$5,IF(T22>0,0,$B$11-U22)+IF(V22>0,0,$C$11-W22)) -> -200.6025 | Z22: =IF(OR(B22="",NOT($H22="")),"",ROUND(_xlfn.FORECAST.LINEAR($I22,INDEX(Z$3:Z$13,MATCH($I22,$Y$3:$Y$13,1)):INDEX(Z$3:Z$13,MATCH($I22,$Y$3:$Y$13,1)+1),INDEX($Y$3:$Y$13,MATCH($I22,$Y$3:$Y$13,1)):INDEX($Y$3:$Y$13,MATCH($I22,$Y$3:$Y$13,1)+1)),0)) | AA22: =IF(OR(C22="",NOT($H22="")),"",ROUND(_xlfn.FORECAST.LINEAR($I22,INDEX(AA$3:AA$13,MATCH($I22,$Y$3:$Y$13,1)):INDEX(AA$3:AA$13,MATCH($I22,$Y$3:$Y$13,1)+1),INDEX($Y$3:$Y$13,MATCH($I22,$Y$3:$Y$13,1)):INDEX($Y$3:$Y$13,MATCH($I22,$Y$3:$Y$13,1)+1)),0)) | AB22: =IF(OR(D22="",NOT($H22="")),"",ROUND(_xlfn.FORECAST.LINEAR($S22,INDEX(AB$3:AB$13,MATCH($S22,$Y$3:$Y$13,1)):INDEX(AB$3:AB$13,MATCH($S22,$Y$3:$Y$13,1)+1),INDEX($Y$3:$Y$13,MATCH($S22,$Y$3:$Y$13,1)):INDEX($Y$3:$Y$13,MATCH($S22,$Y$3:$Y$13,1)+1)),0)) | AC22: =IF(OR(E22="",NOT($H22="")),"",ROUND(_xlfn.FORECAST.LINEAR($S22,INDEX(AC$3:AC$13,MATCH($S22,$Y$3:$Y$13,1)):INDEX(AC$3:AC$13,MATCH($S22,$Y$3:$Y$13,1)+1),INDEX($Y$3:$Y$13,MATCH($S22,$Y$3:$Y$13,1)):INDEX($Y$3:$Y$13,MATCH($S22,$Y$3:$Y$13,1)+1)),0)) | AD22: =IF(OR(F22="",NOT($H22="")),"",ROUND(_xlfn.FORECAST.LINEAR($S22,INDEX(AD$3:AD$13,MATCH($S22,$Y$3:$Y$13,1)):INDEX(AD$3:AD$13,MATCH($S22,$Y$3:$Y$13,1)+1),INDEX($Y$3:$Y$13,MATCH($S22,$Y$3:$Y$13,1)):INDEX($Y$3:$Y$13,MATCH($S22,$Y$3:$Y$13,1)+1)),0)) | AE22: =IF(OR(G22="",NOT($H22="")),"",ROUND(_xlfn.FORECAST.LINEAR($S22,INDEX(AE$3:AE$13,MATCH($S22,$Y$3:$Y$13,1)):INDEX(AE$3:AE$13,MATCH($S22,$Y$3:$Y$13,1)+1),INDEX($Y$3:$Y$13,MATCH($S22,$Y$3:$Y$13,1)):INDEX($Y$3:$Y$13,MATCH($S22,$Y$3:$Y$13,1)+1)),0)) | AF22: =IF($H22="",SUM(Z22:AE22),"") | AG22: =IF(AND($AF22=$AF$17,B22=1),B$9,"") | AH22: =IF(AND($AF22=$AF$17,C22=1),C$9,"") | AI22: =IF(AND($AF22=$AF$17,D22=1),D$9,"") | AJ22: =IF(AND($AF22=$AF$17,E22=1),E$9,"") | AK22: =IF(AND($AF22=$AF$17,F22=1),F$9,"") | AL22: =IF(AND($AF22=$AF$17,G22=1),G$9,"")
C23: 1 | H23: =IF($R$8>$J23,"Insufficient pwr",IF(OR(($M23-$T23-$V23)>0,$X23<$Q$5),"Insufficient PTI",IF(OR(($M23+$U23+$W23)<0,$Y23<$Q$5),"Insufficient PTO",IF(($P23-$R23)<0,"Insufficient AUX","")))) -> Insufficient PTO | I23: =$R$8/$J23 -> 0.65448948 | J23: =B23*B$10+D23*D$10+E23*E$10+F23*F$10+G23*G$10+C23*C$10 -> 24000 | K23: =IF($B23,$B$10)+IF($C23,$C$10) -> 24000 | L23: =(IF($B23,$B$10)+IF($C23,$C$10))*$I23 -> 15707.747 | M23: =$O$5-$L23 -> -4244.7475 | N23: =IF(AND($B23="",$M23>0),MIN($M23,$B$11),0) -> 0 | O23: =IF($M23<0,0,$M23+$Q23-$N23-$V23) -> 0 | P23: =IF($D23,$D$10)+IF($E23,$E$10)+IF($F23,$F$10)+IF($G23,$G$10) -> 0 | Q23: =IF($M23<0,0,$M23*$I$4) -> 0 | R23: =(IF($D23,$D$10)+IF($E23,$E$10)+IF($F23,$F$10)+IF($G23,$G$10))*$I23+$Q23 -> 0 | S23: =IF($P23=0,0,$R23/$P23) -> 0 | T23: =IF($M23<0,0,MIN(($N23+$O23),$B$11)) -> 0 | U23: =IF(AND($B23=1,$M23<0),MIN(ABS($M23),$B$13),0) -> 0 | V23: =IF($M23<0,0,MIN(($M23-$N23),$C$11)) -> 0 | W23: =IF(AND($C23=1,$M23<0),MIN((ABS($M23)-$U23),$C$13),0) -> 3250 | X23: =IF(IF(U23>0,0,$B$11-T23)+IF(W23>0,0,$C$11-V23)>$Q$5,$Q$5,IF(U23>0,0,$B$11-T23)+IF(W23>0,0,$C$11-V23)) -> -200.6025 | Y23: =IF(IF(T23>0,0,$B$11-U23)+IF(V23>0,0,$C$11-W23)>$Q$5,$Q$5,IF(T23>0,0,$B$11-U23)+IF(V23>0,0,$C$11-W23)) -> -200.6025 | Z23: =IF(OR(B23="",NOT($H23="")),"",ROUND(_xlfn.FORECAST.LINEAR($I23,INDEX(Z$3:Z$13,MATCH($I23,$Y$3:$Y$13,1)):INDEX(Z$3:Z$13,MATCH($I23,$Y$3:$Y$13,1)+1),INDEX($Y$3:$Y$13,MATCH($I23,$Y$3:$Y$13,1)):INDEX($Y$3:$Y$13,MATCH($I23,$Y$3:$Y$13,1)+1)),0)) | AA23: =IF(OR(C23="",NOT($H23="")),"",ROUND(_xlfn.FORECAST.LINEAR($I23,INDEX(AA$3:AA$13,MATCH($I23,$Y$3:$Y$13,1)):INDEX(AA$3:AA$13,MATCH($I23,$Y$3:$Y$13,1)+1),INDEX($Y$3:$Y$13,MATCH($I23,$Y$3:$Y$13,1)):INDEX($Y$3:$Y$13,MATCH($I23,$Y$3:$Y$13,1)+1)),0)) | AB23: =IF(OR(D23="",NOT($H23="")),"",ROUND(_xlfn.FORECAST.LINEAR($S23,INDEX(AB$3:AB$13,MATCH($S23,$Y$3:$Y$13,1)):INDEX(AB$3:AB$13,MATCH($S23,$Y$3:$Y$13,1)+1),INDEX($Y$3:$Y$13,MATCH($S23,$Y$3:$Y$13,1)):INDEX($Y$3:$Y$13,MATCH($S23,$Y$3:$Y$13,1)+1)),0)) | AC23: =IF(OR(E23="",NOT($H23="")),"",ROUND(_xlfn.FORECAST.LINEAR($S23,INDEX(AC$3:AC$13,MATCH($S23,$Y$3:$Y$13,1)):INDEX(AC$3:AC$13,MATCH($S23,$Y$3:$Y$13,1)+1),INDEX($Y$3:$Y$13,MATCH($S23,$Y$3:$Y$13,1)):INDEX($Y$3:$Y$13,MATCH($S23,$Y$3:$Y$13,1)+1)),0)) | AD23: =IF(OR(F23="",NOT($H23="")),"",ROUND(_xlfn.FORECAST.LINEAR($S23,INDEX(AD$3:AD$13,MATCH($S23,$Y$3:$Y$13,1)):INDEX(AD$3:AD$13,MATCH($S23,$Y$3:$Y$13,1)+1),INDEX($Y$3:$Y$13,MATCH($S23,$Y$3:$Y$13,1)):INDEX($Y$3:$Y$13,MATCH($S23,$Y$3:$Y$13,1)+1)),0)) | AE23: =IF(OR(G23="",NOT($H23="")),"",ROUND(_xlfn.FORECAST.LINEAR($S23,INDEX(AE$3:AE$13,MATCH($S23,$Y$3:$Y$13,1)):INDEX(AE$3:AE$13,MATCH($S23,$Y$3:$Y$13,1)+1),INDEX($Y$3:$Y$13,MATCH($S23,$Y$3:$Y$13,1)):INDEX($Y$3:$Y$13,MATCH($S23,$Y$3:$Y$13,1)+1)),0)) | AF23: =IF($H23="",SUM(Z23:AE23),"") | AG23: =IF(AND($AF23=$AF$17,B23=1),B$9,"") | AH23: =IF(AND($AF23=$AF$17,C23=1),C$9,"") | AI23: =IF(AND($AF23=$AF$17,D23=1),D$9,"") | AJ23: =IF(AND($AF23=$AF$17,E23=1),E$9,"") | AK23: =IF(AND($AF23=$AF$17,F23=1),F$9,"") | AL23: =IF(AND($AF23=$AF$17,G23=1),G$9,"")
D24: 1 | E24: 1 | H24: =IF($R$8>$J24,"Insufficient pwr",IF(OR(($M24-$T24-$V24)>0,$X24<$Q$5),"Insufficient PTI",IF(OR(($M24+$U24+$W24)<0,$Y24<$Q$5),"Insufficient PTO",IF(($P24-$R24)<0,"Insufficient AUX","")))) -> Insufficient pwr | I24: =$R$8/$J24 -> 1.9634684 | J24: =B24*B$10+D24*D$10+E24*E$10+F24*F$10+G24*G$10+C24*C$10 -> 8000 | K24: =IF($B24,$B$10)+IF($C24,$C$10) -> 0 | L24: =(IF($B24,$B$10)+IF($C24,$C$10))*$I24 -> 0 | M24: =$O$5-$L24 -> 11463 | N24: =IF(AND($B24="",$M24>0),MIN($M24,$B$11),0) -> 3250 | O24: =IF($M24<0,0,$M24+$Q24-$N24-$V24) -> 5536.15 | P24: =IF($D24,$D$10)+IF($E24,$E$10)+IF($F24,$F$10)+IF($G24,$G$10) -> 8000 | Q24: =IF($M24<0,0,$M24*$I$4) -> 573.15 | R24: =(IF($D24,$D$10)+IF($E24,$E$10)+IF($F24,$F$10)+IF($G24,$G$10))*$I24+$Q24 -> 16280.897 | S24: =IF($P24=0,0,$R24/$P24) -> 2.0351122 | T24: =IF($M24<0,0,MIN(($N24+$O24),$B$11)) -> 3250 | U24: =IF(AND($B24=1,$M24<0),MIN(ABS($M24),$B$13),0) -> 0 | V24: =IF($M24<0,0,MIN(($M24-$N24),$C$11)) -> 3250 | W24: =IF(AND($C24=1,$M24<0),MIN((ABS($M24)-$U24),$C$13),0) -> 0 | X24: =IF(IF(U24>0,0,$B$11-T24)+IF(W24>0,0,$C$11-V24)>$Q$5,$Q$5,IF(U24>0,0,$B$11-T24)+IF(W24>0,0,$C$11-V24)) -> -200.6025 | Y24: =IF(IF(T24>0,0,$B$11-U24)+IF(V24>0,0,$C$11-W24)>$Q$5,$Q$5,IF(T24>0,0,$B$11-U24)+IF(V24>0,0,$C$11-W24)) -> -200.6025 | Z24: =IF(OR(B24="",NOT($H24="")),"",ROUND(_xlfn.FORECAST.LINEAR($I24,INDEX(Z$3:Z$13,MATCH($I24,$Y$3:$Y$13,1)):INDEX(Z$3:Z$13,MATCH($I24,$Y$3:$Y$13,1)+1),INDEX($Y$3:$Y$13,MATCH($I24,$Y$3:$Y$13,1)):INDEX($Y$3:$Y$13,MATCH($I24,$Y$3:$Y$13,1)+1)),0)) | AA24: =IF(OR(C24="",NOT($H24="")),"",ROUND(_xlfn.FORECAST.LINEAR($I24,INDEX(AA$3:AA$13,MATCH($I24,$Y$3:$Y$13,1)):INDEX(AA$3:AA$13,MATCH($I24,$Y$3:$Y$13,1)+1),INDEX($Y$3:$Y$13,MATCH($I24,$Y$3:$Y$13,1)):INDEX($Y$3:$Y$13,MATCH($I24,$Y$3:$Y$13,1)+1)),0)) | AB24: =IF(OR(D24="",NOT($H24="")),"",ROUND(_xlfn.FORECAST.LINEAR($S24,INDEX(AB$3:AB$13,MATCH($S24,$Y$3:$Y$13,1)):INDEX(AB$3:AB$13,MATCH($S24,$Y$3:$Y$13,1)+1),INDEX($Y$3:$Y$13,MATCH($S24,$Y$3:$Y$13,1)):INDEX($Y$3:$Y$13,MATCH($S24,$Y$3:$Y$13,1)+1)),0)) | AC24: =IF(OR(E24="",NOT($H24="")),"",ROUND(_xlfn.FORECAST.LINEAR($S24,INDEX(AC$3:AC$13,MATCH($S24,$Y$3:$Y$13,1)):INDEX(AC$3:AC$13,MATCH($S24,$Y$3:$Y$13,1)+1),INDEX($Y$3:$Y$13,MATCH($S24,$Y$3:$Y$13,1)):INDEX($Y$3:$Y$13,MATCH($S24,$Y$3:$Y$13,1)+1)),0)) | AD24: =IF(OR(F24="",NOT($H24="")),"",ROUND(_xlfn.FORECAST.LINEAR($S24,INDEX(AD$3:AD$13,MATCH($S24,$Y$3:$Y$13,1)):INDEX(AD$3:AD$13,MATCH($S24,$Y$3:$Y$13,1)+1),INDEX($Y$3:$Y$13,MATCH($S24,$Y$3:$Y$13,1)):INDEX($Y$3:$Y$13,MATCH($S24,$Y$3:$Y$13,1)+1)),0)) | AE24: =IF(OR(G24="",NOT($H24="")),"",ROUND(_xlfn.FORECAST.LINEAR($S24,INDEX(AE$3:AE$13,MATCH($S24,$Y$3:$Y$13,1)):INDEX(AE$3:AE$13,MATCH($S24,$Y$3:$Y$13,1)+1),INDEX($Y$3:$Y$13,MATCH($S24,$Y$3:$Y$13,1)):INDEX($Y$3:$Y$13,MATCH($S24,$Y$3:$Y$13,1)+1)),0)) | AF24: =IF($H24="",SUM(Z24:AE24),"") | AG24: =IF(AND($AF24=$AF$17,B24=1),B$9,"") | AH24: =IF(AND($AF24=$AF$17,C24=1),C$9,"") | AI24: =IF(AND($AF24=$AF$17,D24=1),D$9,"") | AJ24: =IF(AND($AF24=$AF$17,E24=1),E$9,"") | AK24: =IF(AND($AF24=$AF$17,F24=1),F$9,"") | AL24: =IF(AND($AF24=$AF$17,G24=1),G$9,"")
D25: 1 | F25: 1 | H25: =IF($R$8>$J25,"Insufficient pwr",IF(OR(($M25-$T25-$V25)>0,$X25<$Q$5),"Insufficient PTI",IF(OR(($M25+$U25+$W25)<0,$Y25<$Q$5),"Insufficient PTO",IF(($P25-$R25)<0,"Insufficient AUX","")))) -> Insufficient pwr | I25: =$R$8/$J25 -> 1.9634684 | J25: =B25*B$10+D25*D$10+E25*E$10+F25*F$10+G25*G$10+C25*C$10 -> 8000 | K25: =IF($B25,$B$10)+IF($C25,$C$10) -> 0 | L25: =(IF($B25,$B$10)+IF($C25,$C$10))*$I25 -> 0 | M25: =$O$5-$L25 -> 11463 | N25: =IF(AND($B25="",$M25>0),MIN($M25,$B$11),0) -> 3250 | O25: =IF($M25<0,0,$M25+$Q25-$N25-$V25) -> 5536.15 | P25: =IF($D25,$D$10)+IF($E25,$E$10)+IF($F25,$F$10)+IF($G25,$G$10) -> 8000 | Q25: =IF($M25<0,0,$M25*$I$4) -> 573.15 | R25: =(IF($D25,$D$10)+IF($E25,$E$10)+IF($F25,$F$10)+IF($G25,$G$10))*$I25+$Q25 -> 16280.897 | S25: =IF($P25=0,0,$R25/$P25) -> 2.0351122 | T25: =IF($M25<0,0,MIN(($N25+$O25),$B$11)) -> 3250 | U25: =IF(AND($B25=1,$M25<0),MIN(ABS($M25),$B$13),0) -> 0 | V25: =IF($M25<0,0,MIN(($M25-$N25),$C$11)) -> 3250 | W25: =IF(AND($C25=1,$M25<0),MIN((ABS($M25)-$U25),$C$13),0) -> 0 | X25: =IF(IF(U25>0,0,$B$11-T25)+IF(W25>0,0,$C$11-V25)>$Q$5,$Q$5,IF(U25>0,0,$B$11-T25)+IF(W25>0,0,$C$11-V25)) -> -200.6025 | Y25: =IF(IF(T25>0,0,$B$11-U25)+IF(V25>0,0,$C$11-W25)>$Q$5,$Q$5,IF(T25>0,0,$B$11-U25)+IF(V25>0,0,$C$11-W25)) -> -200.6025 | Z25: =IF(OR(B25="",NOT($H25="")),"",ROUND(_xlfn.FORECAST.LINEAR($I25,INDEX(Z$3:Z$13,MATCH($I25,$Y$3:$Y$13,1)):INDEX(Z$3:Z$13,MATCH($I25,$Y$3:$Y$13,1)+1),INDEX($Y$3:$Y$13,MATCH($I25,$Y$3:$Y$13,1)):INDEX($Y$3:$Y$13,MATCH($I25,$Y$3:$Y$13,1)+1)),0)) | AA25: =IF(OR(C25="",NOT($H25="")),"",ROUND(_xlfn.FORECAST.LINEAR($I25,INDEX(AA$3:AA$13,MATCH($I25,$Y$3:$Y$13,1)):INDEX(AA$3:AA$13,MATCH($I25,$Y$3:$Y$13,1)+1),INDEX($Y$3:$Y$13,MATCH($I25,$Y$3:$Y$13,1)):INDEX($Y$3:$Y$13,MATCH($I25,$Y$3:$Y$13,1)+1)),0)) | AB25: =IF(OR(D25="",NOT($H25="")),"",ROUND(_xlfn.FORECAST.LINEAR($S25,INDEX(AB$3:AB$13,MATCH($S25,$Y$3:$Y$13,1)):INDEX(AB$3:AB$13,MATCH($S25,$Y$3:$Y$13,1)+1),INDEX($Y$3:$Y$13,MATCH($S25,$Y$3:$Y$13,1)):INDEX($Y$3:$Y$13,MATCH($S25,$Y$3:$Y$13,1)+1)),0)) | AC25: =IF(OR(E25="",NOT($H25="")),"",ROUND(_xlfn.FORECAST.LINEAR($S25,INDEX(AC$3:AC$13,MATCH($S25,$Y$3:$Y$13,1)):INDEX(AC$3:AC$13,MATCH($S25,$Y$3:$Y$13,1)+1),INDEX($Y$3:$Y$13,MATCH($S25,$Y$3:$Y$13,1)):INDEX($Y$3:$Y$13,MATCH($S25,$Y$3:$Y$13,1)+1)),0)) | AD25: =IF(OR(F25="",NOT($H25="")),"",ROUND(_xlfn.FORECAST.LINEAR($S25,INDEX(AD$3:AD$13,MATCH($S25,$Y$3:$Y$13,1)):INDEX(AD$3:AD$13,MATCH($S25,$Y$3:$Y$13,1)+1),INDEX($Y$3:$Y$13,MATCH($S25,$Y$3:$Y$13,1)):INDEX($Y$3:$Y$13,MATCH($S25,$Y$3:$Y$13,1)+1)),0)) | AE25: =IF(OR(G25="",NOT($H25="")),"",ROUND(_xlfn.FORECAST.LINEAR($S25,INDEX(AE$3:AE$13,MATCH($S25,$Y$3:$Y$13,1)):INDEX(AE$3:AE$13,MATCH($S25,$Y$3:$Y$13,1)+1),INDEX($Y$3:$Y$13,MATCH($S25,$Y$3:$Y$13,1)):INDEX($Y$3:$Y$13,MATCH($S25,$Y$3:$Y$13,1)+1)),0)) | AF25: =IF($H25="",SUM(Z25:AE25),"") | AG25: =IF(AND($AF25=$AF$17,B25=1),B$9,"") | AH25: =IF(AND($AF25=$AF$17,C25=1),C$9,"") | AI25: =IF(AND($AF25=$AF$17,D25=1),D$9,"") | AJ25: =IF(AND($AF25=$AF$17,E25=1),E$9,"") | AK25: =IF(AND($AF25=$AF$17,F25=1),F$9,"") | AL25: =IF(AND($AF25=$AF$17,G25=1),G$9,"")
D26: 1 | G26: 1 | H26: =IF($R$8>$J26,"Insufficient pwr",IF(OR(($M26-$T26-$V26)>0,$X26<$Q$5),"Insufficient PTI",IF(OR(($M26+$U26+$W26)<0,$Y26<$Q$5),"Insufficient PTO",IF(($P26-$R26)<0,"Insufficient AUX","")))) -> Insufficient pwr | I26: =$R$8/$J26 -> 1.9634684 | J26: =B26*B$10+D26*D$10+E26*E$10+F26*F$10+G26*G$10+C26*C$10 -> 8000 | K26: =IF($B26,$B$10)+IF($C26,$C$10) -> 0 | L26: =(IF($B26,$B$10)+IF($C26,$C$10))*$I26 -> 0 | M26: =$O$5-$L26 -> 11463 | N26: =IF(AND($B26="",$M26>0),MIN($M26,$B$11),0) -> 3250 | O26: =IF($M26<0,0,$M26+$Q26-$N26-$V26) -> 5536.15 | P26: =IF($D26,$D$10)+IF($E26,$E$10)+IF($F26,$F$10)+IF($G26,$G$10) -> 8000 | Q26: =IF($M26<0,0,$M26*$I$4) -> 573.15 | R26: =(IF($D26,$D$10)+IF($E26,$E$10)+IF($F26,$F$10)+IF($G26,$G$10))*$I26+$Q26 -> 16280.897 | S26: =IF($P26=0,0,$R26/$P26) -> 2.0351122 | T26: =IF($M26<0,0,MIN(($N26+$O26),$B$11)) -> 3250 | U26: =IF(AND($B26=1,$M26<0),MIN(ABS($M26),$B$13),0) -> 0 | V26: =IF($M26<0,0,MIN(($M26-$N26),$C$11)) -> 3250 | W26: =IF(AND($C26=1,$M26<0),MIN((ABS($M26)-$U26),$C$13),0) -> 0 | X26: =IF(IF(U26>0,0,$B$11-T26)+IF(W26>0,0,$C$11-V26)>$Q$5,$Q$5,IF(U26>0,0,$B$11-T26)+IF(W26>0,0,$C$11-V26)) -> -200.6025 | Y26: =IF(IF(T26>0,0,$B$11-U26)+IF(V26>0,0,$C$11-W26)>$Q$5,$Q$5,IF(T26>0,0,$B$11-U26)+IF(V26>0,0,$C$11-W26)) -> -200.6025 | Z26: =IF(OR(B26="",NOT($H26="")),"",ROUND(_xlfn.FORECAST.LINEAR($I26,INDEX(Z$3:Z$13,MATCH($I26,$Y$3:$Y$13,1)):INDEX(Z$3:Z$13,MATCH($I26,$Y$3:$Y$13,1)+1),INDEX($Y$3:$Y$13,MATCH($I26,$Y$3:$Y$13,1)):INDEX($Y$3:$Y$13,MATCH($I26,$Y$3:$Y$13,1)+1)),0)) | AA26: =IF(OR(C26="",NOT($H26="")),"",ROUND(_xlfn.FORECAST.LINEAR($I26,INDEX(AA$3:AA$13,MATCH($I26,$Y$3:$Y$13,1)):INDEX(AA$3:AA$13,MATCH($I26,$Y$3:$Y$13,1)+1),INDEX($Y$3:$Y$13,MATCH($I26,$Y$3:$Y$13,1)):INDEX($Y$3:$Y$13,MATCH($I26,$Y$3:$Y$13,1)+1)),0)) | AB26: =IF(OR(D26="",NOT($H26="")),"",ROUND(_xlfn.FORECAST.LINEAR($S26,INDEX(AB$3:AB$13,MATCH($S26,$Y$3:$Y$13,1)):INDEX(AB$3:AB$13,MATCH($S26,$Y$3:$Y$13,1)+1),INDEX($Y$3:$Y$13,MATCH($S26,$Y$3:$Y$13,1)):INDEX($Y$3:$Y$13,MATCH($S26,$Y$3:$Y$13,1)+1)),0)) | AC26: =IF(OR(E26="",NOT($H26="")),"",ROUND(_xlfn.FORECAST.LINEAR($S26,INDEX(AC$3:AC$13,MATCH($S26,$Y$3:$Y$13,1)):INDEX(AC$3:AC$13,MATCH($S26,$Y$3:$Y$13,1)+1),INDEX($Y$3:$Y$13,MATCH($S26,$Y$3:$Y$13,1)):INDEX($Y$3:$Y$13,MATCH($S26,$Y$3:$Y$13,1)+1)),0)) | AD26: =IF(OR(F26="",NOT($H26="")),"",ROUND(_xlfn.FORECAST.LINEAR($S26,INDEX(AD$3:AD$13,MATCH($S26,$Y$3:$Y$13,1)):INDEX(AD$3:AD$13,MATCH($S26,$Y$3:$Y$13,1)+1),INDEX($Y$3:$Y$13,MATCH($S26,$Y$3:$Y$13,1)):INDEX($Y$3:$Y$13,MATCH($S26,$Y$3:$Y$13,1)+1)),0)) | AE26: =IF(OR(G26="",NOT($H26="")),"",ROUND(_xlfn.FORECAST.LINEAR($S26,INDEX(AE$3:AE$13,MATCH($S26,$Y$3:$Y$13,1)):INDEX(AE$3:AE$13,MATCH($S26,$Y$3:$Y$13,1)+1),INDEX($Y$3:$Y$13,MATCH($S26,$Y$3:$Y$13,1)):INDEX($Y$3:$Y$13,MATCH($S26,$Y$3:$Y$13,1)+1)),0)) | AF26: =IF($H26="",SUM(Z26:AE26),"") | AG26: =IF(AND($AF26=$AF$17,B26=1),B$9,"") | AH26: =IF(AND($AF26=$AF$17,C26=1),C$9,"") | AI26: =IF(AND($AF26=$AF$17,D26=1),D$9,"") | AJ26: =IF(AND($AF26=$AF$17,E26=1),E$9,"") | AK26: =IF(AND($AF26=$AF$17,F26=1),F$9,"") | AL26: =IF(AND($AF26=$AF$17,G26=1),G$9,"")
E27: 1 | F27: 1 | H27: =IF($R$8>$J27,"Insufficient pwr",IF(OR(($M27-$T27-$V27)>0,$X27<$Q$5),"Insufficient PTI",IF(OR(($M27+$U27+$W27)<0,$Y27<$Q$5),"Insufficient PTO",IF(($P27-$R27)<0,"Insufficient AUX","")))) -> Insufficient pwr | I27: =$R$8/$J27 -> 1.9634684 | J27: =B27*B$10+D27*D$10+E27*E$10+F27*F$10+G27*G$10+C27*C$10 -> 8000 | K27: =IF($B27,$B$10)+IF($C27,$C$10) -> 0 | L27: =(IF($B27,$B$10)+IF($C27,$C$10))*$I27 -> 0 | M27: =$O$5-$L27 -> 11463 | N27: =IF(AND($B27="",$M27>0),MIN($M27,$B$11),0) -> 3250 | O27: =IF($M27<0,0,$M27+$Q27-$N27-$V27) -> 5536.15 | P27: =IF($D27,$D$10)+IF($E27,$E$10)+IF($F27,$F$10)+IF($G27,$G$10) -> 8000 | Q27: =IF($M27<0,0,$M27*$I$4) -> 573.15 | R27: =(IF($D27,$D$10)+IF($E27,$E$10)+IF($F27,$F$10)+IF($G27,$G$10))*$I27+$Q27 -> 16280.897 | S27: =IF($P27=0,0,$R27/$P27) -> 2.0351122 | T27: =IF($M27<0,0,MIN(($N27+$O27),$B$11)) -> 3250 | U27: =IF(AND($B27=1,$M27<0),MIN(ABS($M27),$B$13),0) -> 0 | V27: =IF($M27<0,0,MIN(($M27-$N27),$C$11)) -> 3250 | W27: =IF(AND($C27=1,$M27<0),MIN((ABS($M27)-$U27),$C$13),0) -> 0 | X27: =IF(IF(U27>0,0,$B$11-T27)+IF(W27>0,0,$C$11-V27)>$Q$5,$Q$5,IF(U27>0,0,$B$11-T27)+IF(W27>0,0,$C$11-V27)) -> -200.6025 | Y27: =IF(IF(T27>0,0,$B$11-U27)+IF(V27>0,0,$C$11-W27)>$Q$5,$Q$5,IF(T27>0,0,$B$11-U27)+IF(V27>0,0,$C$11-W27)) -> -200.6025 | Z27: =IF(OR(B27="",NOT($H27="")),"",ROUND(_xlfn.FORECAST.LINEAR($I27,INDEX(Z$3:Z$13,MATCH($I27,$Y$3:$Y$13,1)):INDEX(Z$3:Z$13,MATCH($I27,$Y$3:$Y$13,1)+1),INDEX($Y$3:$Y$13,MATCH($I27,$Y$3:$Y$13,1)):INDEX($Y$3:$Y$13,MATCH($I27,$Y$3:$Y$13,1)+1)),0)) | AA27: =IF(OR(C27="",NOT($H27="")),"",ROUND(_xlfn.FORECAST.LINEAR($I27,INDEX(AA$3:AA$13,MATCH($I27,$Y$3:$Y$13,1)):INDEX(AA$3:AA$13,MATCH($I27,$Y$3:$Y$13,1)+1),INDEX($Y$3:$Y$13,MATCH($I27,$Y$3:$Y$13,1)):INDEX($Y$3:$Y$13,MATCH($I27,$Y$3:$Y$13,1)+1)),0)) | AB27: =IF(OR(D27="",NOT($H27="")),"",ROUND(_xlfn.FORECAST.LINEAR($S27,INDEX(AB$3:AB$13,MATCH($S27,$Y$3:$Y$13,1)):INDEX(AB$3:AB$13,MATCH($S27,$Y$3:$Y$13,1)+1),INDEX($Y$3:$Y$13,MATCH($S27,$Y$3:$Y$13,1)):INDEX($Y$3:$Y$13,MATCH($S27,$Y$3:$Y$13,1)+1)),0)) | AC27: =IF(OR(E27="",NOT($H27="")),"",ROUND(_xlfn.FORECAST.LINEAR($S27,INDEX(AC$3:AC$13,MATCH($S27,$Y$3:$Y$13,1)):INDEX(AC$3:AC$13,MATCH($S27,$Y$3:$Y$13,1)+1),INDEX($Y$3:$Y$13,MATCH($S27,$Y$3:$Y$13,1)):INDEX($Y$3:$Y$13,MATCH($S27,$Y$3:$Y$13,1)+1)),0)) | AD27: =IF(OR(F27="",NOT($H27="")),"",ROUND(_xlfn.FORECAST.LINEAR($S27,INDEX(AD$3:AD$13,MATCH($S27,$Y$3:$Y$13,1)):INDEX(AD$3:AD$13,MATCH($S27,$Y$3:$Y$13,1)+1),INDEX($Y$3:$Y$13,MATCH($S27,$Y$3:$Y$13,1)):INDEX($Y$3:$Y$13,MATCH($S27,$Y$3:$Y$13,1)+1)),0)) | AE27: =IF(OR(G27="",NOT($H27="")),"",ROUND(_xlfn.FORECAST.LINEAR($S27,INDEX(AE$3:AE$13,MATCH($S27,$Y$3:$Y$13,1)):INDEX(AE$3:AE$13,MATCH($S27,$Y$3:$Y$13,1)+1),INDEX($Y$3:$Y$13,MATCH($S27,$Y$3:$Y$13,1)):INDEX($Y$3:$Y$13,MATCH($S27,$Y$3:$Y$13,1)+1)),0)) | AF27: =IF($H27="",SUM(Z27:AE27),"") | AG27: =IF(AND($AF27=$AF$17,B27=1),B$9,"") | AH27: =IF(AND($AF27=$AF$17,C27=1),C$9,"") | AI27: =IF(AND($AF27=$AF$17,D27=1),D$9,"") | AJ27: =IF(AND($AF27=$AF$17,E27=1),E$9,"") | AK27: =IF(AND($AF27=$AF$17,F27=1),F$9,"") | AL27: =IF(AND($AF27=$AF$17,G27=1),G$9,"")
E28: 1 | G28: 1 | H28: =IF($R$8>$J28,"Insufficient pwr",IF(OR(($M28-$T28-$V28)>0,$X28<$Q$5),"Insufficient PTI",IF(OR(($M28+$U28+$W28)<0,$Y28<$Q$5),"Insufficient PTO",IF(($P28-$R28)<0,"Insufficient AUX","")))) -> Insufficient pwr | I28: =$R$8/$J28 -> 1.9634684 | J28: =B28*B$10+D28*D$10+E28*E$10+F28*F$10+G28*G$10+C28*C$10 -> 8000 | K28: =IF($B28,$B$10)+IF($C28,$C$10) -> 0 | L28: =(IF($B28,$B$10)+IF($C28,$C$10))*$I28 -> 0 | M28: =$O$5-$L28 -> 11463 | N28: =IF(AND($B28="",$M28>0),MIN($M28,$B$11),0) -> 3250 | O28: =IF($M28<0,0,$M28+$Q28-$N28-$V28) -> 5536.15 | P28: =IF($D28,$D$10)+IF($E28,$E$10)+IF($F28,$F$10)+IF($G28,$G$10) -> 8000 | Q28: =IF($M28<0,0,$M28*$I$4) -> 573.15 | R28: =(IF($D28,$D$10)+IF($E28,$E$10)+IF($F28,$F$10)+IF($G28,$G$10))*$I28+$Q28 -> 16280.897 | S28: =IF($P28=0,0,$R28/$P28) -> 2.0351122 | T28: =IF($M28<0,0,MIN(($N28+$O28),$B$11)) -> 3250 | U28: =IF(AND($B28=1,$M28<0),MIN(ABS($M28),$B$13),0) -> 0 | V28: =IF($M28<0,0,MIN(($M28-$N28),$C$11)) -> 3250 | W28: =IF(AND($C28=1,$M28<0),MIN((ABS($M28)-$U28),$C$13),0) -> 0 | X28: =IF(IF(U28>0,0,$B$11-T28)+IF(W28>0,0,$C$11-V28)>$Q$5,$Q$5,IF(U28>0,0,$B$11-T28)+IF(W28>0,0,$C$11-V28)) -> -200.6025 | Y28: =IF(IF(T28>0,0,$B$11-U28)+IF(V28>0,0,$C$11-W28)>$Q$5,$Q$5,IF(T28>0,0,$B$11-U28)+IF(V28>0,0,$C$11-W28)) -> -200.6025 | Z28: =IF(OR(B28="",NOT($H28="")),"",ROUND(_xlfn.FORECAST.LINEAR($I28,INDEX(Z$3:Z$13,MATCH($I28,$Y$3:$Y$13,1)):INDEX(Z$3:Z$13,MATCH($I28,$Y$3:$Y$13,1)+1),INDEX($Y$3:$Y$13,MATCH($I28,$Y$3:$Y$13,1)):INDEX($Y$3:$Y$13,MATCH($I28,$Y$3:$Y$13,1)+1)),0)) | AA28: =IF(OR(C28="",NOT($H28="")),"",ROUND(_xlfn.FORECAST.LINEAR($I28,INDEX(AA$3:AA$13,MATCH($I28,$Y$3:$Y$13,1)):INDEX(AA$3:AA$13,MATCH($I28,$Y$3:$Y$13,1)+1),INDEX($Y$3:$Y$13,MATCH($I28,$Y$3:$Y$13,1)):INDEX($Y$3:$Y$13,MATCH($I28,$Y$3:$Y$13,1)+1)),0)) | AB28: =IF(OR(D28="",NOT($H28="")),"",ROUND(_xlfn.FORECAST.LINEAR($S28,INDEX(AB$3:AB$13,MATCH($S28,$Y$3:$Y$13,1)):INDEX(AB$3:AB$13,MATCH($S28,$Y$3:$Y$13,1)+1),INDEX($Y$3:$Y$13,MATCH($S28,$Y$3:$Y$13,1)):INDEX($Y$3:$Y$13,MATCH($S28,$Y$3:$Y$13,1)+1)),0)) | AC28: =IF(OR(E28="",NOT($H28="")),"",ROUND(_xlfn.FORECAST.LINEAR($S28,INDEX(AC$3:AC$13,MATCH($S28,$Y$3:$Y$13,1)):INDEX(AC$3:AC$13,MATCH($S28,$Y$3:$Y$13,1)+1),INDEX($Y$3:$Y$13,MATCH($S28,$Y$3:$Y$13,1)):INDEX($Y$3:$Y$13,MATCH($S28,$Y$3:$Y$13,1)+1)),0)) | AD28: =IF(OR(F28="",NOT($H28="")),"",ROUND(_xlfn.FORECAST.LINEAR($S28,INDEX(AD$3:AD$13,MATCH($S28,$Y$3:$Y$13,1)):INDEX(AD$3:AD$13,MATCH($S28,$Y$3:$Y$13,1)+1),INDEX($Y$3:$Y$13,MATCH($S28,$Y$3:$Y$13,1)):INDEX($Y$3:$Y$13,MATCH($S28,$Y$3:$Y$13,1)+1)),0)) | AE28: =IF(OR(G28="",NOT($H28="")),"",ROUND(_xlfn.FORECAST.LINEAR($S28,INDEX(AE$3:AE$13,MATCH($S28,$Y$3:$Y$13,1)):INDEX(AE$3:AE$13,MATCH($S28,$Y$3:$Y$13,1)+1),INDEX($Y$3:$Y$13,MATCH($S28,$Y$3:$Y$13,1)):INDEX($Y$3:$Y$13,MATCH($S28,$Y$3:$Y$13,1)+1)),0)) | AF28: =IF($H28="",SUM(Z28:AE28),"") | AG28: =IF(AND($AF28=$AF$17,B28=1),B$9,"") | AH28: =IF(AND($AF28=$AF$17,C28=1),C$9,"") | AI28: =IF(AND($AF28=$AF$17,D28=1),D$9,"") | AJ28: =IF(AND($AF28=$AF$17,E28=1),E$9,"") | AK28: =IF(AND($AF28=$AF$17,F28=1),F$9,"") | AL28: =IF(AND($AF28=$AF$17,G28=1),G$9,"")
F29: 1 | G29: 1 | H29: =IF($R$8>$J29,"Insufficient pwr",IF(OR(($M29-$T29-$V29)>0,$X29<$Q$5),"Insufficient PTI",IF(OR(($M29+$U29+$W29)<0,$Y29<$Q$5),"Insufficient PTO",IF(($P29-$R29)<0,"Insufficient AUX","")))) -> Insufficient pwr | I29: =$R$8/$J29 -> 1.9634684 | J29: =B29*B$10+D29*D$10+E29*E$10+F29*F$10+G29*G$10+C29*C$10 -> 8000 | K29: =IF($B29,$B$10)+IF($C29,$C$10) -> 0 | L29: =(IF($B29,$B$10)+IF($C29,$C$10))*$I29 -> 0 | M29: =$O$5-$L29 -> 11463 | N29: =IF(AND($B29="",$M29>0),MIN($M29,$B$11),0) -> 3250 | O29: =IF($M29<0,0,$M29+$Q29-$N29-$V29) -> 5536.15 | P29: =IF($D29,$D$10)+IF($E29,$E$10)+IF($F29,$F$10)+IF($G29,$G$10) -> 8000 | Q29: =IF($M29<0,0,$M29*$I$4) -> 573.15 | R29: =(IF($D29,$D$10)+IF($E29,$E$10)+IF($F29,$F$10)+IF($G29,$G$10))*$I29+$Q29 -> 16280.897 | S29: =IF($P29=0,0,$R29/$P29) -> 2.0351122 | T29: =IF($M29<0,0,MIN(($N29+$O29),$B$11)) -> 3250 | U29: =IF(AND($B29=1,$M29<0),MIN(ABS($M29),$B$13),0) -> 0 | V29: =IF($M29<0,0,MIN(($M29-$N29),$C$11)) -> 3250 | W29: =IF(AND($C29=1,$M29<0),MIN((ABS($M29)-$U29),$C$13),0) -> 0 | X29: =IF(IF(U29>0,0,$B$11-T29)+IF(W29>0,0,$C$11-V29)>$Q$5,$Q$5,IF(U29>0,0,$B$11-T29)+IF(W29>0,0,$C$11-V29)) -> -200.6025 | Y29: =IF(IF(T29>0,0,$B$11-U29)+IF(V29>0,0,$C$11-W29)>$Q$5,$Q$5,IF(T29>0,0,$B$11-U29)+IF(V29>0,0,$C$11-W29)) -> -200.6025 | Z29: =IF(OR(B29="",NOT($H29="")),"",ROUND(_xlfn.FORECAST.LINEAR($I29,INDEX(Z$3:Z$13,MATCH($I29,$Y$3:$Y$13,1)):INDEX(Z$3:Z$13,MATCH($I29,$Y$3:$Y$13,1)+1),INDEX($Y$3:$Y$13,MATCH($I29,$Y$3:$Y$13,1)):INDEX($Y$3:$Y$13,MATCH($I29,$Y$3:$Y$13,1)+1)),0)) | AA29: =IF(OR(C29="",NOT($H29="")),"",ROUND(_xlfn.FORECAST.LINEAR($I29,INDEX(AA$3:AA$13,MATCH($I29,$Y$3:$Y$13,1)):INDEX(AA$3:AA$13,MATCH($I29,$Y$3:$Y$13,1)+1),INDEX($Y$3:$Y$13,MATCH($I29,$Y$3:$Y$13,1)):INDEX($Y$3:$Y$13,MATCH($I29,$Y$3:$Y$13,1)+1)),0)) | AB29: =IF(OR(D29="",NOT($H29="")),"",ROUND(_xlfn.FORECAST.LINEAR($S29,INDEX(AB$3:AB$13,MATCH($S29,$Y$3:$Y$13,1)):INDEX(AB$3:AB$13,MATCH($S29,$Y$3:$Y$13,1)+1),INDEX($Y$3:$Y$13,MATCH($S29,$Y$3:$Y$13,1)):INDEX($Y$3:$Y$13,MATCH($S29,$Y$3:$Y$13,1)+1)),0)) | AC29: =IF(OR(E29="",NOT($H29="")),"",ROUND(_xlfn.FORECAST.LINEAR($S29,INDEX(AC$3:AC$13,MATCH($S29,$Y$3:$Y$13,1)):INDEX(AC$3:AC$13,MATCH($S29,$Y$3:$Y$13,1)+1),INDEX($Y$3:$Y$13,MATCH($S29,$Y$3:$Y$13,1)):INDEX($Y$3:$Y$13,MATCH($S29,$Y$3:$Y$13,1)+1)),0)) | AD29: =IF(OR(F29="",NOT($H29="")),"",ROUND(_xlfn.FORECAST.LINEAR($S29,INDEX(AD$3:AD$13,MATCH($S29,$Y$3:$Y$13,1)):INDEX(AD$3:AD$13,MATCH($S29,$Y$3:$Y$13,1)+1),INDEX($Y$3:$Y$13,MATCH($S29,$Y$3:$Y$13,1)):INDEX($Y$3:$Y$13,MATCH($S29,$Y$3:$Y$13,1)+1)),0)) | AE29: =IF(OR(G29="",NOT($H29="")),"",ROUND(_xlfn.FORECAST.LINEAR($S29,INDEX(AE$3:AE$13,MATCH($S29,$Y$3:$Y$13,1)):INDEX(AE$3:AE$13,MATCH($S29,$Y$3:$Y$13,1)+1),INDEX($Y$3:$Y$13,MATCH($S29,$Y$3:$Y$13,1)):INDEX($Y$3:$Y$13,MATCH($S29,$Y$3:$Y$13,1)+1)),0)) | AF29: =IF($H29="",SUM(Z29:AE29),"") | AG29: =IF(AND($AF29=$AF$17,B29=1),B$9,"") | AH29: =IF(AND($AF29=$AF$17,C29=1),C$9,"") | AI29: =IF(AND($AF29=$AF$17,D29=1),D$9,"") | AJ29: =IF(AND($AF29=$AF$17,E29=1),E$9,"") | AK29: =IF(AND($AF29=$AF$17,F29=1),F$9,"") | AL29: =IF(AND($AF29=$AF$17,G29=1),G$9,"")
B30: 1 | D30: 1 | H30: =IF($R$8>$J30,"Insufficient pwr",IF(OR(($M30-$T30-$V30)>0,$X30<$Q$5),"Insufficient PTI",IF(OR(($M30+$U30+$W30)<0,$Y30<$Q$5),"Insufficient PTO",IF(($P30-$R30)<0,"Insufficient AUX","")))) | I30: =$R$8/$J30 -> 0.56099098 | J30: =B30*B$10+D30*D$10+E30*E$10+F30*F$10+G30*G$10+C30*C$10 -> 28000 | K30: =IF($B30,$B$10)+IF($C30,$C$10) -> 24000 | L30: =(IF($B30,$B$10)+IF($C30,$C$10))*$I30 -> 13463.784 | M30: =$O$5-$L30 -> -2000.7836 | N30: =IF(AND($B30="",$M30>0),MIN($M30,$B$11),0) -> 0 | O30: =IF($M30<0,0,$M30+$Q30-$N30-$V30) -> 0 | P30: =IF($D30,$D$10)+IF($E30,$E$10)+IF($F30,$F$10)+IF($G30,$G$10) -> 4000 | Q30: =IF($M30<0,0,$M30*$I$4) -> 0 | R30: =(IF($D30,$D$10)+IF($E30,$E$10)+IF($F30,$F$10)+IF($G30,$G$10))*$I30+$Q30 -> 2243.9639 | S30: =IF($P30=0,0,$R30/$P30) -> 0.56099098 | T30: =IF($M30<0,0,MIN(($N30+$O30),$B$11)) -> 0 | U30: =IF(AND($B30=1,$M30<0),MIN(ABS($M30),$B$13),0) -> 2000.7836 | V30: =IF($M30<0,0,MIN(($M30-$N30),$C$11)) -> 0 | W30: =IF(AND($C30=1,$M30<0),MIN((ABS($M30)-$U30),$C$13),0) -> 0 | X30: =IF(IF(U30>0,0,$B$11-T30)+IF(W30>0,0,$C$11-V30)>$Q$5,$Q$5,IF(U30>0,0,$B$11-T30)+IF(W30>0,0,$C$11-V30)) -> -200.6025 | Y30: =IF(IF(T30>0,0,$B$11-U30)+IF(V30>0,0,$C$11-W30)>$Q$5,$Q$5,IF(T30>0,0,$B$11-U30)+IF(V30>0,0,$C$11-W30)) -> -200.6025 | Z30: =IF(OR(B30="",NOT($H30="")),"",ROUND(_xlfn.FORECAST.LINEAR($I30,INDEX(Z$3:Z$13,MATCH($I30,$Y$3:$Y$13,1)):INDEX(Z$3:Z$13,MATCH($I30,$Y$3:$Y$13,1)+1),INDEX($Y$3:$Y$13,MATCH($I30,$Y$3:$Y$13,1)):INDEX($Y$3:$Y$13,MATCH($I30,$Y$3:$Y$13,1)+1)),0)) -> 166 | AA30: =IF(OR(C30="",NOT($H30="")),"",ROUND(_xlfn.FORECAST.LINEAR($I30,INDEX(AA$3:AA$13,MATCH($I30,$Y$3:$Y$13,1)):INDEX(AA$3:AA$13,MATCH($I30,$Y$3:$Y$13,1)+1),INDEX($Y$3:$Y$13,MATCH($I30,$Y$3:$Y$13,1)):INDEX($Y$3:$Y$13,MATCH($I30,$Y$3:$Y$13,1)+1)),0)) | AB30: =IF(OR(D30="",NOT($H30="")),"",ROUND(_xlfn.FORECAST.LINEAR($S30,INDEX(AB$3:AB$13,MATCH($S30,$Y$3:$Y$13,1)):INDEX(AB$3:AB$13,MATCH($S30,$Y$3:$Y$13,1)+1),INDEX($Y$3:$Y$13,MATCH($S30,$Y$3:$Y$13,1)):INDEX($Y$3:$Y$13,MATCH($S30,$Y$3:$Y$13,1)+1)),0)) -> 196 | AC30: =IF(OR(E30="",NOT($H30="")),"",ROUND(_xlfn.FORECAST.LINEAR($S30,INDEX(AC$3:AC$13,MATCH($S30,$Y$3:$Y$13,1)):INDEX(AC$3:AC$13,MATCH($S30,$Y$3:$Y$13,1)+1),INDEX($Y$3:$Y$13,MATCH($S30,$Y$3:$Y$13,1)):INDEX($Y$3:$Y$13,MATCH($S30,$Y$3:$Y$13,1)+1)),0)) | AD30: =IF(OR(F30="",NOT($H30="")),"",ROUND(_xlfn.FORECAST.LINEAR($S30,INDEX(AD$3:AD$13,MATCH($S30,$Y$3:$Y$13,1)):INDEX(AD$3:AD$13,MATCH($S30,$Y$3:$Y$13,1)+1),INDEX($Y$3:$Y$13,MATCH($S30,$Y$3:$Y$13,1)):INDEX($Y$3:$Y$13,MATCH($S30,$Y$3:$Y$13,1)+1)),0)) | AE30: =IF(OR(G30="",NOT($H30="")),"",ROUND(_xlfn.FORECAST.LINEAR($S30,INDEX(AE$3:AE$13,MATCH($S30,$Y$3:$Y$13,1)):INDEX(AE$3:AE$13,MATCH($S30,$Y$3:$Y$13,1)+1),INDEX($Y$3:$Y$13,MATCH($S30,$Y$3:$Y$13,1)):INDEX($Y$3:$Y$13,MATCH($S30,$Y$3:$Y$13,1)+1)),0)) | AF30: =IF($H30="",SUM(Z30:AE30),"") -> 362 | AG30: =IF(AND($AF30=$AF$17,B30=1),B$9,"") | AH30: =IF(AND($AF30=$AF$17,C30=1),C$9,"") | AI30: =IF(AND($AF30=$AF$17,D30=1),D$9,"") | AJ30: =IF(AND($AF30=$AF$17,E30=1),E$9,"") | AK30: =IF(AND($AF30=$AF$17,F30=1),F$9,"") | AL30: =IF(AND($AF30=$AF$17,G30=1),G$9,"")
B31: 1 | E31: 1 | H31: =IF($R$8>$J31,"Insufficient pwr",IF(OR(($M31-$T31-$V31)>0,$X31<$Q$5),"Insufficient PTI",IF(OR(($M31+$U31+$W31)<0,$Y31<$Q$5),"Insufficient PTO",IF(($P31-$R31)<0,"Insufficient AUX","")))) | I31: =$R$8/$J31 -> 0.56099098 | J31: =B31*B$10+D31*D$10+E31*E$10+F31*F$10+G31*G$10+C31*C$10 -> 28000 | K31: =IF($B31,$B$10)+IF($C31,$C$10) -> 24000 | L31: =(IF($B31,$B$10)+IF($C31,$C$10))*$I31 -> 13463.784 | M31: =$O$5-$L31 -> -2000.7836 | N31: =IF(AND($B31="",$M31>0),MIN($M31,$B$11),0) -> 0 | O31: =IF($M31<0,0,$M31+$Q31-$N31-$V31) -> 0 | P31: =IF($D31,$D$10)+IF($E31,$E$10)+IF($F31,$F$10)+IF($G31,$G$10) -> 4000 | Q31: =IF($M31<0,0,$M31*$I$4) -> 0 | R31: =(IF($D31,$D$10)+IF($E31,$E$10)+IF($F31,$F$10)+IF($G31,$G$10))*$I31+$Q31 -> 2243.9639 | S31: =IF($P31=0,0,$R31/$P31) -> 0.56099098 | T31: =IF($M31<0,0,MIN(($N31+$O31),$B$11)) -> 0 | U31: =IF(AND($B31=1,$M31<0),MIN(ABS($M31),$B$13),0) -> 2000.7836 | V31: =IF($M31<0,0,MIN(($M31-$N31),$C$11)) -> 0 | W31: =IF(AND($C31=1,$M31<0),MIN((ABS($M31)-$U31),$C$13),0) -> 0 | X31: =IF(IF(U31>0,0,$B$11-T31)+IF(W31>0,0,$C$11-V31)>$Q$5,$Q$5,IF(U31>0,0,$B$11-T31)+IF(W31>0,0,$C$11-V31)) -> -200.6025 | Y31: =IF(IF(T31>0,0,$B$11-U31)+IF(V31>0,0,$C$11-W31)>$Q$5,$Q$5,IF(T31>0,0,$B$11-U31)+IF(V31>0,0,$C$11-W31)) -> -200.6025 | Z31: =IF(OR(B31="",NOT($H31="")),"",ROUND(_xlfn.FORECAST.LINEAR($I31,INDEX(Z$3:Z$13,MATCH($I31,$Y$3:$Y$13,1)):INDEX(Z$3:Z$13,MATCH($I31,$Y$3:$Y$13,1)+1),INDEX($Y$3:$Y$13,MATCH($I31,$Y$3:$Y$13,1)):INDEX($Y$3:$Y$13,MATCH($I31,$Y$3:$Y$13,1)+1)),0)) -> 166 | AA31: =IF(OR(C31="",NOT($H31="")),"",ROUND(_xlfn.FORECAST.LINEAR($I31,INDEX(AA$3:AA$13,MATCH($I31,$Y$3:$Y$13,1)):INDEX(AA$3:AA$13,MATCH($I31,$Y$3:$Y$13,1)+1),INDEX($Y$3:$Y$13,MATCH($I31,$Y$3:$Y$13,1)):INDEX($Y$3:$Y$13,MATCH($I31,$Y$3:$Y$13,1)+1)),0)) | AB31: =IF(OR(D31="",NOT($H31="")),"",ROUND(_xlfn.FORECAST.LINEAR($S31,INDEX(AB$3:AB$13,MATCH($S31,$Y$3:$Y$13,1)):INDEX(AB$3:AB$13,MATCH($S31,$Y$3:$Y$13,1)+1),INDEX($Y$3:$Y$13,MATCH($S31,$Y$3:$Y$13,1)):INDEX($Y$3:$Y$13,MATCH($S31,$Y$3:$Y$13,1)+1)),0)) | AC31: =IF(OR(E31="",NOT($H31="")),"",ROUND(_xlfn.FORECAST.LINEAR($S31,INDEX(AC$3:AC$13,MATCH($S31,$Y$3:$Y$13,1)):INDEX(AC$3:AC$13,MATCH($S31,$Y$3:$Y$13,1)+1),INDEX($Y$3:$Y$13,MATCH($S31,$Y$3:$Y$13,1)):INDEX($Y$3:$Y$13,MATCH($S31,$Y$3:$Y$13,1)+1)),0)) -> 196 | AD31: =IF(OR(F31="",NOT($H31="")),"",ROUND(_xlfn.FORECAST.LINEAR($S31,INDEX(AD$3:AD$13,MATCH($S31,$Y$3:$Y$13,1)):INDEX(AD$3:AD$13,MATCH($S31,$Y$3:$Y$13,1)+1),INDEX($Y$3:$Y$13,MATCH($S31,$Y$3:$Y$13,1)):INDEX($Y$3:$Y$13,MATCH($S31,$Y$3:$Y$13,1)+1)),0)) | AE31: =IF(OR(G31="",NOT($H31="")),"",ROUND(_xlfn.FORECAST.LINEAR($S31,INDEX(AE$3:AE$13,MATCH($S31,$Y$3:$Y$13,1)):INDEX(AE$3:AE$13,MATCH($S31,$Y$3:$Y$13,1)+1),INDEX($Y$3:$Y$13,MATCH($S31,$Y$3:$Y$13,1)):INDEX($Y$3:$Y$13,MATCH($S31,$Y$3:$Y$13,1)+1)),0)) | AF31: =IF($H31="",SUM(Z31:AE31),"") -> 362 | AG31: =IF(AND($AF31=$AF$17,B31=1),B$9,"") | AH31: =IF(AND($AF31=$AF$17,C31=1),C$9,"") | AI31: =IF(AND($AF31=$AF$17,D31=1),D$9,"") | AJ31: =IF(AND($AF31=$AF$17,E31=1),E$9,"") | AK31: =IF(AND($AF31=$AF$17,F31=1),F$9,"") | AL31: =IF(AND($AF31=$AF$17,G31=1),G$9,"")
B32: 1 | F32: 1 | H32: =IF($R$8>$J32,"Insufficient pwr",IF(OR(($M32-$T32-$V32)>0,$X32<$Q$5),"Insufficient PTI",IF(OR(($M32+$U32+$W32)<0,$Y32<$Q$5),"Insufficient PTO",IF(($P32-$R32)<0,"Insufficient AUX","")))) | I32: =$R$8/$J32 -> 0.56099098 | J32: =B32*B$10+D32*D$10+E32*E$10+F32*F$10+G32*G$10+C32*C$10 -> 28000 | K32: =IF($B32,$B$10)+IF($C32,$C$10) -> 24000 | L32: =(IF($B32,$B$10)+IF($C32,$C$10))*$I32 -> 13463.784 | M32: =$O$5-$L32 -> -2000.7836 | N32: =IF(AND($B32="",$M32>0),MIN($M32,$B$11),0) -> 0 | O32: =IF($M32<0,0,$M32+$Q32-$N32-$V32) -> 0 | P32: =IF($D32,$D$10)+IF($E32,$E$10)+IF($F32,$F$10)+IF($G32,$G$10) -> 4000 | Q32: =IF($M32<0,0,$M32*$I$4) -> 0 | R32: =(IF($D32,$D$10)+IF($E32,$E$10)+IF($F32,$F$10)+IF($G32,$G$10))*$I32+$Q32 -> 2243.9639 | S32: =IF($P32=0,0,$R32/$P32) -> 0.56099098 | T32: =IF($M32<0,0,MIN(($N32+$O32),$B$11)) -> 0 | U32: =IF(AND($B32=1,$M32<0),MIN(ABS($M32),$B$13),0) -> 2000.7836 | V32: =IF($M32<0,0,MIN(($M32-$N32),$C$11)) -> 0 | W32: =IF(AND($C32=1,$M32<0),MIN((ABS($M32)-$U32),$C$13),0) -> 0 | X32: =IF(IF(U32>0,0,$B$11-T32)+IF(W32>0,0,$C$11-V32)>$Q$5,$Q$5,IF(U32>0,0,$B$11-T32)+IF(W32>0,0,$C$11-V32)) -> -200.6025 | Y32: =IF(IF(T32>0,0,$B$11-U32)+IF(V32>0,0,$C$11-W32)>$Q$5,$Q$5,IF(T32>0,0,$B$11-U32)+IF(V32>0,0,$C$11-W32)) -> -200.6025 | Z32: =IF(OR(B32="",NOT($H32="")),"",ROUND(_xlfn.FORECAST.LINEAR($I32,INDEX(Z$3:Z$13,MATCH($I32,$Y$3:$Y$13,1)):INDEX(Z$3:Z$13,MATCH($I32,$Y$3:$Y$13,1)+1),INDEX($Y$3:$Y$13,MATCH($I32,$Y$3:$Y$13,1)):INDEX($Y$3:$Y$13,MATCH($I32,$Y$3:$Y$13,1)+1)),0)) -> 166 | AA32: =IF(OR(C32="",NOT($H32="")),"",ROUND(_xlfn.FORECAST.LINEAR($I32,INDEX(AA$3:AA$13,MATCH($I32,$Y$3:$Y$13,1)):INDEX(AA$3:AA$13,MATCH($I32,$Y$3:$Y$13,1)+1),INDEX($Y$3:$Y$13,MATCH($I32,$Y$3:$Y$13,1)):INDEX($Y$3:$Y$13,MATCH($I32,$Y$3:$Y$13,1)+1)),0)) | AB32: =IF(OR(D32="",NOT($H32="")),"",ROUND(_xlfn.FORECAST.LINEAR($S32,INDEX(AB$3:AB$13,MATCH($S32,$Y$3:$Y$13,1)):INDEX(AB$3:AB$13,MATCH($S32,$Y$3:$Y$13,1)+1),INDEX($Y$3:$Y$13,MATCH($S32,$Y$3:$Y$13,1)):INDEX($Y$3:$Y$13,MATCH($S32,$Y$3:$Y$13,1)+1)),0)) | AC32: =IF(OR(E32="",NOT($H32="")),"",ROUND(_xlfn.FORECAST.LINEAR($S32,INDEX(AC$3:AC$13,MATCH($S32,$Y$3:$Y$13,1)):INDEX(AC$3:AC$13,MATCH($S32,$Y$3:$Y$13,1)+1),INDEX($Y$3:$Y$13,MATCH($S32,$Y$3:$Y$13,1)):INDEX($Y$3:$Y$13,MATCH($S32,$Y$3:$Y$13,1)+1)),0)) | AD32: =IF(OR(F32="",NOT($H32="")),"",ROUND(_xlfn.FORECAST.LINEAR($S32,INDEX(AD$3:AD$13,MATCH($S32,$Y$3:$Y$13,1)):INDEX(AD$3:AD$13,MATCH($S32,$Y$3:$Y$13,1)+1),INDEX($Y$3:$Y$13,MATCH($S32,$Y$3:$Y$13,1)):INDEX($Y$3:$Y$13,MATCH($S32,$Y$3:$Y$13,1)+1)),0)) -> 188 | AE32: =IF(OR(G32="",NOT($H32="")),"",ROUND(_xlfn.FORECAST.LINEAR($S32,INDEX(AE$3:AE$13,MATCH($S32,$Y$3:$Y$13,1)):INDEX(AE$3:AE$13,MATCH($S32,$Y$3:$Y$13,1)+1),INDEX($Y$3:$Y$13,MATCH($S32,$Y$3:$Y$13,1)):INDEX($Y$3:$Y$13,MATCH($S32,$Y$3:$Y$13,1)+1)),0)) | AF32: =IF($H32="",SUM(Z32:AE32),"") -> 354 | AG32: =IF(AND($AF32=$AF$17,B32=1),B$9,"") | AH32: =IF(AND($AF32=$AF$17,C32=1),C$9,"") | AI32: =IF(AND($AF32=$AF$17,D32=1),D$9,"") | AJ32: =IF(AND($AF32=$AF$17,E32=1),E$9,"") | AK32: =IF(AND($AF32=$AF$17,F32=1),F$9,"") | AL32: =IF(AND($AF32=$AF$17,G32=1),G$9,"")
B33: 1 | G33: 1 | H33: =IF($R$8>$J33,"Insufficient pwr",IF(OR(($M33-$T33-$V33)>0,$X33<$Q$5),"Insufficient PTI",IF(OR(($M33+$U33+$W33)<0,$Y33<$Q$5),"Insufficient PTO",IF(($P33-$R33)<0,"Insufficient AUX","")))) | I33: =$R$8/$J33 -> 0.56099098 | J33: =B33*B$10+D33*D$10+E33*E$10+F33*F$10+G33*G$10+C33*C$10 -> 28000 | K33: =IF($B33,$B$10)+IF($C33,$C$10) -> 24000 | L33: =(IF($B33,$B$10)+IF($C33,$C$10))*$I33 -> 13463.784 | M33: =$O$5-$L33 -> -2000.7836 | N33: =IF(AND($B33="",$M33>0),MIN($M33,$B$11),0) -> 0 | O33: =IF($M33<0,0,$M33+$Q33-$N33-$V33) -> 0 | P33: =IF($D33,$D$10)+IF($E33,$E$10)+IF($F33,$F$10)+IF($G33,$G$10) -> 4000 | Q33: =IF($M33<0,0,$M33*$I$4) -> 0 | R33: =(IF($D33,$D$10)+IF($E33,$E$10)+IF($F33,$F$10)+IF($G33,$G$10))*$I33+$Q33 -> 2243.9639 | S33: =IF($P33=0,0,$R33/$P33) -> 0.56099098 | T33: =IF($M33<0,0,MIN(($N33+$O33),$B$11)) -> 0 | U33: =IF(AND($B33=1,$M33<0),MIN(ABS($M33),$B$13),0) -> 2000.7836 | V33: =IF($M33<0,0,MIN(($M33-$N33),$C$11)) -> 0 | W33: =IF(AND($C33=1,$M33<0),MIN((ABS($M33)-$U33),$C$13),0) -> 0 | X33: =IF(IF(U33>0,0,$B$11-T33)+IF(W33>0,0,$C$11-V33)>$Q$5,$Q$5,IF(U33>0,0,$B$11-T33)+IF(W33>0,0,$C$11-V33)) -> -200.6025 | Y33: =IF(IF(T33>0,0,$B$11-U33)+IF(V33>0,0,$C$11-W33)>$Q$5,$Q$5,IF(T33>0,0,$B$11-U33)+IF(V33>0,0,$C$11-W33)) -> -200.6025 | Z33: =IF(OR(B33="",NOT($H33="")),"",ROUND(_xlfn.FORECAST.LINEAR($I33,INDEX(Z$3:Z$13,MATCH($I33,$Y$3:$Y$13,1)):INDEX(Z$3:Z$13,MATCH($I33,$Y$3:$Y$13,1)+1),INDEX($Y$3:$Y$13,MATCH($I33,$Y$3:$Y$13,1)):INDEX($Y$3:$Y$13,MATCH($I33,$Y$3:$Y$13,1)+1)),0)) -> 166 | AA33: =IF(OR(C33="",NOT($H33="")),"",ROUND(_xlfn.FORECAST.LINEAR($I33,INDEX(AA$3:AA$13,MATCH($I33,$Y$3:$Y$13,1)):INDEX(AA$3:AA$13,MATCH($I33,$Y$3:$Y$13,1)+1),INDEX($Y$3:$Y$13,MATCH($I33,$Y$3:$Y$13,1)):INDEX($Y$3:$Y$13,MATCH($I33,$Y$3:$Y$13,1)+1)),0)) | AB33: =IF(OR(D33="",NOT($H33="")),"",ROUND(_xlfn.FORECAST.LINEAR($S33,INDEX(AB$3:AB$13,MATCH($S33,$Y$3:$Y$13,1)):INDEX(AB$3:AB$13,MATCH($S33,$Y$3:$Y$13,1)+1),INDEX($Y$3:$Y$13,MATCH($S33,$Y$3:$Y$13,1)):INDEX($Y$3:$Y$13,MATCH($S33,$Y$3:$Y$13,1)+1)),0)) | AC33: =IF(OR(E33="",NOT($H33="")),"",ROUND(_xlfn.FORECAST.LINEAR($S33,INDEX(AC$3:AC$13,MATCH($S33,$Y$3:$Y$13,1)):INDEX(AC$3:AC$13,MATCH($S33,$Y$3:$Y$13,1)+1),INDEX($Y$3:$Y$13,MATCH($S33,$Y$3:$Y$13,1)):INDEX($Y$3:$Y$13,MATCH($S33,$Y$3:$Y$13,1)+1)),0)) | AD33: =IF(OR(F33="",NOT($H33="")),"",ROUND(_xlfn.FORECAST.LINEAR($S33,INDEX(AD$3:AD$13,MATCH($S33,$Y$3:$Y$13,1)):INDEX(AD$3:AD$13,MATCH($S33,$Y$3:$Y$13,1)+1),INDEX($Y$3:$Y$13,MATCH($S33,$Y$3:$Y$13,1)):INDEX($Y$3:$Y$13,MATCH($S33,$Y$3:$Y$13,1)+1)),0)) | AE33: =IF(OR(G33="",NOT($H33="")),"",ROUND(_xlfn.FORECAST.LINEAR($S33,INDEX(AE$3:AE$13,MATCH($S33,$Y$3:$Y$13,1)):INDEX(AE$3:AE$13,MATCH($S33,$Y$3:$Y$13,1)+1),INDEX($Y$3:$Y$13,MATCH($S33,$Y$3:$Y$13,1)):INDEX($Y$3:$Y$13,MATCH($S33,$Y$3:$Y$13,1)+1)),0)) -> 216 | AF33: =IF($H33="",SUM(Z33:AE33),"") -> 382 | AG33: =IF(AND($AF33=$AF$17,B33=1),B$9,"") | AH33: =IF(AND($AF33=$AF$17,C33=1),C$9,"") | AI33: =IF(AND($AF33=$AF$17,D33=1),D$9,"") | AJ33: =IF(AND($AF33=$AF$17,E33=1),E$9,"") | AK33: =IF(AND($AF33=$AF$17,F33=1),F$9,"") | AL33: =IF(AND($AF33=$AF$17,G33=1),G$9,"")
C34: 1 | D34: 1 | H34: =IF($R$8>$J34,"Insufficient pwr",IF(OR(($M34-$T34-$V34)>0,$X34<$Q$5),"Insufficient PTI",IF(OR(($M34+$U34+$W34)<0,$Y34<$Q$5),"Insufficient PTO",IF(($P34-$R34)<0,"Insufficient AUX","")))) | I34: =$R$8/$J34 -> 0.56099098 | J34: =B34*B$10+D34*D$10+E34*E$10+F34*F$10+G34*G$10+C34*C$10 -> 28000 | K34: =IF($B34,$B$10)+IF($C34,$C$10) -> 24000 | L34: =(IF($B34,$B$10)+IF($C34,$C$10))*$I34 -> 13463.784 | M34: =$O$5-$L34 -> -2000.7836 | N34: =IF(AND($B34="",$M34>0),MIN($M34,$B$11),0) -> 0 | O34: =IF($M34<0,0,$M34+$Q34-$N34-$V34) -> 0 | P34: =IF($D34,$D$10)+IF($E34,$E$10)+IF($F34,$F$10)+IF($G34,$G$10) -> 4000 | Q34: =IF($M34<0,0,$M34*$I$4) -> 0 | R34: =(IF($D34,$D$10)+IF($E34,$E$10)+IF($F34,$F$10)+IF($G34,$G$10))*$I34+$Q34 -> 2243.9639 | S34: =IF($P34=0,0,$R34/$P34) -> 0.56099098 | T34: =IF($M34<0,0,MIN(($N34+$O34),$B$11)) -> 0 | U34: =IF(AND($B34=1,$M34<0),MIN(ABS($M34),$B$13),0) -> 0 | V34: =IF($M34<0,0,MIN(($M34-$N34),$C$11)) -> 0 | W34: =IF(AND($C34=1,$M34<0),MIN((ABS($M34)-$U34),$C$13),0) -> 2000.7836 | X34: =IF(IF(U34>0,0,$B$11-T34)+IF(W34>0,0,$C$11-V34)>$Q$5,$Q$5,IF(U34>0,0,$B$11-T34)+IF(W34>0,0,$C$11-V34)) -> -200.6025 | Y34: =IF(IF(T34>0,0,$B$11-U34)+IF(V34>0,0,$C$11-W34)>$Q$5,$Q$5,IF(T34>0,0,$B$11-U34)+IF(V34>0,0,$C$11-W34)) -> -200.6025 | Z34: =IF(OR(B34="",NOT($H34="")),"",ROUND(_xlfn.FORECAST.LINEAR($I34,INDEX(Z$3:Z$13,MATCH($I34,$Y$3:$Y$13,1)):INDEX(Z$3:Z$13,MATCH($I34,$Y$3:$Y$13,1)+1),INDEX($Y$3:$Y$13,MATCH($I34,$Y$3:$Y$13,1)):INDEX($Y$3:$Y$13,MATCH($I34,$Y$3:$Y$13,1)+1)),0)) | AA34: =IF(OR(C34="",NOT($H34="")),"",ROUND(_xlfn.FORECAST.LINEAR($I34,INDEX(AA$3:AA$13,MATCH($I34,$Y$3:$Y$13,1)):INDEX(AA$3:AA$13,MATCH($I34,$Y$3:$Y$13,1)+1),INDEX($Y$3:$Y$13,MATCH($I34,$Y$3:$Y$13,1)):INDEX($Y$3:$Y$13,MATCH($I34,$Y$3:$Y$13,1)+1)),0)) -> 166 | AB34: =IF(OR(D34="",NOT($H34="")),"",ROUND(_xlfn.FORECAST.LINEAR($S34,INDEX(AB$3:AB$13,MATCH($S34,$Y$3:$Y$13,1)):INDEX(AB$3:AB$13,MATCH($S34,$Y$3:$Y$13,1)+1),INDEX($Y$3:$Y$13,MATCH($S34,$Y$3:$Y$13,1)):INDEX($Y$3:$Y$13,MATCH($S34,$Y$3:$Y$13,1)+1)),0)) -> 196 | AC34: =IF(OR(E34="",NOT($H34="")),"",ROUND(_xlfn.FORECAST.LINEAR($S34,INDEX(AC$3:AC$13,MATCH($S34,$Y$3:$Y$13,1)):INDEX(AC$3:AC$13,MATCH($S34,$Y$3:$Y$13,1)+1),INDEX($Y$3:$Y$13,MATCH($S34,$Y$3:$Y$13,1)):INDEX($Y$3:$Y$13,MATCH($S34,$Y$3:$Y$13,1)+1)),0)) | AD34: =IF(OR(F34="",NOT($H34="")),"",ROUND(_xlfn.FORECAST.LINEAR($S34,INDEX(AD$3:AD$13,MATCH($S34,$Y$3:$Y$13,1)):INDEX(AD$3:AD$13,MATCH($S34,$Y$3:$Y$13,1)+1),INDEX($Y$3:$Y$13,MATCH($S34,$Y$3:$Y$13,1)):INDEX($Y$3:$Y$13,MATCH($S34,$Y$3:$Y$13,1)+1)),0)) | AE34: =IF(OR(G34="",NOT($H34="")),"",ROUND(_xlfn.FORECAST.LINEAR($S34,INDEX(AE$3:AE$13,MATCH($S34,$Y$3:$Y$13,1)):INDEX(AE$3:AE$13,MATCH($S34,$Y$3:$Y$13,1)+1),INDEX($Y$3:$Y$13,MATCH($S34,$Y$3:$Y$13,1)):INDEX($Y$3:$Y$13,MATCH($S34,$Y$3:$Y$13,1)+1)),0)) | AF34: =IF($H34="",SUM(Z34:AE34),"") -> 362 | AG34: =IF(AND($AF34=$AF$17,B34=1),B$9,"") | AH34: =IF(AND($AF34=$AF$17,C34=1),C$9,"") | AI34: =IF(AND($AF34=$AF$17,D34=1),D$9,"") | AJ34: =IF(AND($AF34=$AF$17,E34=1),E$9,"") | AK34: =IF(AND($AF34=$AF$17,F34=1),F$9,"") | AL34: =IF(AND($AF34=$AF$17,G34=1),G$9,"")
